INFO 2021-01-02 17:47:25,122 autoreload 597 Watching for file changes with StatReloader
INFO 2021-01-02 18:20:44,163 autoreload 597 Watching for file changes with StatReloader
WARNING 2021-01-02 18:21:01,969 log 228 Not Found: /usernames/1111111/count/
WARNING 2021-01-02 18:21:01,970 basehttp 154 "GET /usernames/1111111/count/ HTTP/1.1" 404 2201
WARNING 2021-01-02 18:21:02,066 log 228 Not Found: /favicon.ico
WARNING 2021-01-02 18:21:02,067 basehttp 154 "GET /favicon.ico HTTP/1.1" 404 2162
WARNING 2021-01-02 18:21:20,438 log 228 Not Found: /usernames/<username>/count/
WARNING 2021-01-02 18:21:20,445 basehttp 154 "GET /usernames/%3Cusername%3E/count/ HTTP/1.1" 404 2226
INFO 2021-01-02 18:21:33,620 autoreload 217 /home/ubuntu/Desktop/test/MeiDuo_test/meiduo_mail/apps/users/urls.py changed, reloading.
INFO 2021-01-02 18:21:34,333 autoreload 597 Watching for file changes with StatReloader
ERROR 2021-01-02 18:21:37,052 log 228 Internal Server Error: /usernames/<username>/count/
Traceback (most recent call last):
  File "/home/ubuntu/.virtualenvs/py3_shunyi_44/lib/python3.6/site-packages/django/core/handlers/exception.py", line 34, in inner
    response = get_response(request)
  File "/home/ubuntu/.virtualenvs/py3_shunyi_44/lib/python3.6/site-packages/django/core/handlers/base.py", line 115, in _get_response
    response = self.process_exception_by_middleware(e, request)
  File "/home/ubuntu/.virtualenvs/py3_shunyi_44/lib/python3.6/site-packages/django/core/handlers/base.py", line 113, in _get_response
    response = wrapped_callback(request, *callback_args, **callback_kwargs)
  File "/home/ubuntu/.virtualenvs/py3_shunyi_44/lib/python3.6/site-packages/django/views/generic/base.py", line 71, in view
    return self.dispatch(request, *args, **kwargs)
  File "/home/ubuntu/.virtualenvs/py3_shunyi_44/lib/python3.6/site-packages/django/views/generic/base.py", line 97, in dispatch
    return handler(request, *args, **kwargs)
TypeError: get() got an unexpected keyword argument 'username'
ERROR 2021-01-02 18:21:37,054 basehttp 154 "GET /usernames/%3Cusername%3E/count/ HTTP/1.1" 500 78946
ERROR 2021-01-02 18:21:42,581 log 228 Internal Server Error: /usernames/111/count/
Traceback (most recent call last):
  File "/home/ubuntu/.virtualenvs/py3_shunyi_44/lib/python3.6/site-packages/django/core/handlers/exception.py", line 34, in inner
    response = get_response(request)
  File "/home/ubuntu/.virtualenvs/py3_shunyi_44/lib/python3.6/site-packages/django/core/handlers/base.py", line 115, in _get_response
    response = self.process_exception_by_middleware(e, request)
  File "/home/ubuntu/.virtualenvs/py3_shunyi_44/lib/python3.6/site-packages/django/core/handlers/base.py", line 113, in _get_response
    response = wrapped_callback(request, *callback_args, **callback_kwargs)
  File "/home/ubuntu/.virtualenvs/py3_shunyi_44/lib/python3.6/site-packages/django/views/generic/base.py", line 71, in view
    return self.dispatch(request, *args, **kwargs)
  File "/home/ubuntu/.virtualenvs/py3_shunyi_44/lib/python3.6/site-packages/django/views/generic/base.py", line 97, in dispatch
    return handler(request, *args, **kwargs)
TypeError: get() got an unexpected keyword argument 'username'
ERROR 2021-01-02 18:21:42,582 basehttp 154 "GET /usernames/111/count/ HTTP/1.1" 500 78591
ERROR 2021-01-02 18:21:57,016 log 228 Internal Server Error: /usernames/<username>/count/
Traceback (most recent call last):
  File "/home/ubuntu/.virtualenvs/py3_shunyi_44/lib/python3.6/site-packages/django/core/handlers/exception.py", line 34, in inner
    response = get_response(request)
  File "/home/ubuntu/.virtualenvs/py3_shunyi_44/lib/python3.6/site-packages/django/core/handlers/base.py", line 115, in _get_response
    response = self.process_exception_by_middleware(e, request)
  File "/home/ubuntu/.virtualenvs/py3_shunyi_44/lib/python3.6/site-packages/django/core/handlers/base.py", line 113, in _get_response
    response = wrapped_callback(request, *callback_args, **callback_kwargs)
  File "/home/ubuntu/.virtualenvs/py3_shunyi_44/lib/python3.6/site-packages/django/views/generic/base.py", line 71, in view
    return self.dispatch(request, *args, **kwargs)
  File "/home/ubuntu/.virtualenvs/py3_shunyi_44/lib/python3.6/site-packages/django/views/generic/base.py", line 97, in dispatch
    return handler(request, *args, **kwargs)
TypeError: get() got an unexpected keyword argument 'username'
ERROR 2021-01-02 18:21:57,017 basehttp 154 "GET /usernames/%3Cusername%3E/count/ HTTP/1.1" 500 78811
WARNING 2021-01-02 18:22:44,014 log 228 Not Found: /
WARNING 2021-01-02 18:22:44,015 basehttp 154 "GET / HTTP/1.1" 404 2112
WARNING 2021-01-02 18:23:02,126 log 228 Not Found: /image_codes/5219f997-deb2-4a68-a808-aadc59cf3aae/
WARNING 2021-01-02 18:23:02,126 basehttp 154 "GET /image_codes/5219f997-deb2-4a68-a808-aadc59cf3aae/ HTTP/1.1" 404 2277
ERROR 2021-01-02 18:23:03,394 log 228 Internal Server Error: /usernames/itcast_01/count/
Traceback (most recent call last):
  File "/home/ubuntu/.virtualenvs/py3_shunyi_44/lib/python3.6/site-packages/django/core/handlers/exception.py", line 34, in inner
    response = get_response(request)
  File "/home/ubuntu/.virtualenvs/py3_shunyi_44/lib/python3.6/site-packages/django/core/handlers/base.py", line 115, in _get_response
    response = self.process_exception_by_middleware(e, request)
  File "/home/ubuntu/.virtualenvs/py3_shunyi_44/lib/python3.6/site-packages/django/core/handlers/base.py", line 113, in _get_response
    response = wrapped_callback(request, *callback_args, **callback_kwargs)
  File "/home/ubuntu/.virtualenvs/py3_shunyi_44/lib/python3.6/site-packages/django/views/generic/base.py", line 71, in view
    return self.dispatch(request, *args, **kwargs)
  File "/home/ubuntu/.virtualenvs/py3_shunyi_44/lib/python3.6/site-packages/django/views/generic/base.py", line 97, in dispatch
    return handler(request, *args, **kwargs)
TypeError: get() got an unexpected keyword argument 'username'
ERROR 2021-01-02 18:23:03,406 basehttp 154 "GET /usernames/itcast_01/count/ HTTP/1.1" 500 78782
ERROR 2021-01-02 18:23:04,114 log 228 Internal Server Error: /usernames/itcast_01/count/
Traceback (most recent call last):
  File "/home/ubuntu/.virtualenvs/py3_shunyi_44/lib/python3.6/site-packages/django/core/handlers/exception.py", line 34, in inner
    response = get_response(request)
  File "/home/ubuntu/.virtualenvs/py3_shunyi_44/lib/python3.6/site-packages/django/core/handlers/base.py", line 115, in _get_response
    response = self.process_exception_by_middleware(e, request)
  File "/home/ubuntu/.virtualenvs/py3_shunyi_44/lib/python3.6/site-packages/django/core/handlers/base.py", line 113, in _get_response
    response = wrapped_callback(request, *callback_args, **callback_kwargs)
  File "/home/ubuntu/.virtualenvs/py3_shunyi_44/lib/python3.6/site-packages/django/views/generic/base.py", line 71, in view
    return self.dispatch(request, *args, **kwargs)
  File "/home/ubuntu/.virtualenvs/py3_shunyi_44/lib/python3.6/site-packages/django/views/generic/base.py", line 97, in dispatch
    return handler(request, *args, **kwargs)
TypeError: get() got an unexpected keyword argument 'username'
ERROR 2021-01-02 18:23:04,116 basehttp 154 "GET /usernames/itcast_01/count/ HTTP/1.1" 500 78782
ERROR 2021-01-02 18:23:06,714 log 228 Internal Server Error: /usernames/itcast_01/count/
Traceback (most recent call last):
  File "/home/ubuntu/.virtualenvs/py3_shunyi_44/lib/python3.6/site-packages/django/core/handlers/exception.py", line 34, in inner
    response = get_response(request)
  File "/home/ubuntu/.virtualenvs/py3_shunyi_44/lib/python3.6/site-packages/django/core/handlers/base.py", line 115, in _get_response
    response = self.process_exception_by_middleware(e, request)
  File "/home/ubuntu/.virtualenvs/py3_shunyi_44/lib/python3.6/site-packages/django/core/handlers/base.py", line 113, in _get_response
    response = wrapped_callback(request, *callback_args, **callback_kwargs)
  File "/home/ubuntu/.virtualenvs/py3_shunyi_44/lib/python3.6/site-packages/django/views/generic/base.py", line 71, in view
    return self.dispatch(request, *args, **kwargs)
  File "/home/ubuntu/.virtualenvs/py3_shunyi_44/lib/python3.6/site-packages/django/views/generic/base.py", line 97, in dispatch
    return handler(request, *args, **kwargs)
TypeError: get() got an unexpected keyword argument 'username'
ERROR 2021-01-02 18:23:06,717 basehttp 154 "GET /usernames/itcast_01/count/ HTTP/1.1" 500 78782
ERROR 2021-01-02 18:23:07,256 log 228 Internal Server Error: /usernames/itcast_01/count/
Traceback (most recent call last):
  File "/home/ubuntu/.virtualenvs/py3_shunyi_44/lib/python3.6/site-packages/django/core/handlers/exception.py", line 34, in inner
    response = get_response(request)
  File "/home/ubuntu/.virtualenvs/py3_shunyi_44/lib/python3.6/site-packages/django/core/handlers/base.py", line 115, in _get_response
    response = self.process_exception_by_middleware(e, request)
  File "/home/ubuntu/.virtualenvs/py3_shunyi_44/lib/python3.6/site-packages/django/core/handlers/base.py", line 113, in _get_response
    response = wrapped_callback(request, *callback_args, **callback_kwargs)
  File "/home/ubuntu/.virtualenvs/py3_shunyi_44/lib/python3.6/site-packages/django/views/generic/base.py", line 71, in view
    return self.dispatch(request, *args, **kwargs)
  File "/home/ubuntu/.virtualenvs/py3_shunyi_44/lib/python3.6/site-packages/django/views/generic/base.py", line 97, in dispatch
    return handler(request, *args, **kwargs)
TypeError: get() got an unexpected keyword argument 'username'
ERROR 2021-01-02 18:23:07,262 basehttp 154 "GET /usernames/itcast_01/count/ HTTP/1.1" 500 78782
ERROR 2021-01-02 18:23:08,427 log 228 Internal Server Error: /usernames/itcast_01/count/
Traceback (most recent call last):
  File "/home/ubuntu/.virtualenvs/py3_shunyi_44/lib/python3.6/site-packages/django/core/handlers/exception.py", line 34, in inner
    response = get_response(request)
  File "/home/ubuntu/.virtualenvs/py3_shunyi_44/lib/python3.6/site-packages/django/core/handlers/base.py", line 115, in _get_response
    response = self.process_exception_by_middleware(e, request)
  File "/home/ubuntu/.virtualenvs/py3_shunyi_44/lib/python3.6/site-packages/django/core/handlers/base.py", line 113, in _get_response
    response = wrapped_callback(request, *callback_args, **callback_kwargs)
  File "/home/ubuntu/.virtualenvs/py3_shunyi_44/lib/python3.6/site-packages/django/views/generic/base.py", line 71, in view
    return self.dispatch(request, *args, **kwargs)
  File "/home/ubuntu/.virtualenvs/py3_shunyi_44/lib/python3.6/site-packages/django/views/generic/base.py", line 97, in dispatch
    return handler(request, *args, **kwargs)
TypeError: get() got an unexpected keyword argument 'username'
ERROR 2021-01-02 18:23:08,428 basehttp 154 "GET /usernames/itcast_01/count/ HTTP/1.1" 500 78782
ERROR 2021-01-02 18:23:14,252 log 228 Internal Server Error: /usernames/itcast_01/count/
Traceback (most recent call last):
  File "/home/ubuntu/.virtualenvs/py3_shunyi_44/lib/python3.6/site-packages/django/core/handlers/exception.py", line 34, in inner
    response = get_response(request)
  File "/home/ubuntu/.virtualenvs/py3_shunyi_44/lib/python3.6/site-packages/django/core/handlers/base.py", line 115, in _get_response
    response = self.process_exception_by_middleware(e, request)
  File "/home/ubuntu/.virtualenvs/py3_shunyi_44/lib/python3.6/site-packages/django/core/handlers/base.py", line 113, in _get_response
    response = wrapped_callback(request, *callback_args, **callback_kwargs)
  File "/home/ubuntu/.virtualenvs/py3_shunyi_44/lib/python3.6/site-packages/django/views/generic/base.py", line 71, in view
    return self.dispatch(request, *args, **kwargs)
  File "/home/ubuntu/.virtualenvs/py3_shunyi_44/lib/python3.6/site-packages/django/views/generic/base.py", line 97, in dispatch
    return handler(request, *args, **kwargs)
TypeError: get() got an unexpected keyword argument 'username'
ERROR 2021-01-02 18:23:14,253 basehttp 154 "GET /usernames/itcast_01/count/ HTTP/1.1" 500 78782
ERROR 2021-01-02 18:23:21,207 log 228 Internal Server Error: /usernames/itcast_01/count/
Traceback (most recent call last):
  File "/home/ubuntu/.virtualenvs/py3_shunyi_44/lib/python3.6/site-packages/django/core/handlers/exception.py", line 34, in inner
    response = get_response(request)
  File "/home/ubuntu/.virtualenvs/py3_shunyi_44/lib/python3.6/site-packages/django/core/handlers/base.py", line 115, in _get_response
    response = self.process_exception_by_middleware(e, request)
  File "/home/ubuntu/.virtualenvs/py3_shunyi_44/lib/python3.6/site-packages/django/core/handlers/base.py", line 113, in _get_response
    response = wrapped_callback(request, *callback_args, **callback_kwargs)
  File "/home/ubuntu/.virtualenvs/py3_shunyi_44/lib/python3.6/site-packages/django/views/generic/base.py", line 71, in view
    return self.dispatch(request, *args, **kwargs)
  File "/home/ubuntu/.virtualenvs/py3_shunyi_44/lib/python3.6/site-packages/django/views/generic/base.py", line 97, in dispatch
    return handler(request, *args, **kwargs)
TypeError: get() got an unexpected keyword argument 'username'
ERROR 2021-01-02 18:23:21,213 basehttp 154 "GET /usernames/itcast_01/count/ HTTP/1.1" 500 78782
ERROR 2021-01-02 18:23:22,757 log 228 Internal Server Error: /usernames/itcast_01/count/
Traceback (most recent call last):
  File "/home/ubuntu/.virtualenvs/py3_shunyi_44/lib/python3.6/site-packages/django/core/handlers/exception.py", line 34, in inner
    response = get_response(request)
  File "/home/ubuntu/.virtualenvs/py3_shunyi_44/lib/python3.6/site-packages/django/core/handlers/base.py", line 115, in _get_response
    response = self.process_exception_by_middleware(e, request)
  File "/home/ubuntu/.virtualenvs/py3_shunyi_44/lib/python3.6/site-packages/django/core/handlers/base.py", line 113, in _get_response
    response = wrapped_callback(request, *callback_args, **callback_kwargs)
  File "/home/ubuntu/.virtualenvs/py3_shunyi_44/lib/python3.6/site-packages/django/views/generic/base.py", line 71, in view
    return self.dispatch(request, *args, **kwargs)
  File "/home/ubuntu/.virtualenvs/py3_shunyi_44/lib/python3.6/site-packages/django/views/generic/base.py", line 97, in dispatch
    return handler(request, *args, **kwargs)
TypeError: get() got an unexpected keyword argument 'username'
ERROR 2021-01-02 18:23:22,760 basehttp 154 "GET /usernames/itcast_01/count/ HTTP/1.1" 500 78782
ERROR 2021-01-02 18:23:24,560 log 228 Internal Server Error: /usernames/itcast_01/count/
Traceback (most recent call last):
  File "/home/ubuntu/.virtualenvs/py3_shunyi_44/lib/python3.6/site-packages/django/core/handlers/exception.py", line 34, in inner
    response = get_response(request)
  File "/home/ubuntu/.virtualenvs/py3_shunyi_44/lib/python3.6/site-packages/django/core/handlers/base.py", line 115, in _get_response
    response = self.process_exception_by_middleware(e, request)
  File "/home/ubuntu/.virtualenvs/py3_shunyi_44/lib/python3.6/site-packages/django/core/handlers/base.py", line 113, in _get_response
    response = wrapped_callback(request, *callback_args, **callback_kwargs)
  File "/home/ubuntu/.virtualenvs/py3_shunyi_44/lib/python3.6/site-packages/django/views/generic/base.py", line 71, in view
    return self.dispatch(request, *args, **kwargs)
  File "/home/ubuntu/.virtualenvs/py3_shunyi_44/lib/python3.6/site-packages/django/views/generic/base.py", line 97, in dispatch
    return handler(request, *args, **kwargs)
TypeError: get() got an unexpected keyword argument 'username'
ERROR 2021-01-02 18:23:24,564 basehttp 154 "GET /usernames/itcast_01/count/ HTTP/1.1" 500 78782
ERROR 2021-01-02 18:23:25,521 log 228 Internal Server Error: /usernames/itcast_01/count/
Traceback (most recent call last):
  File "/home/ubuntu/.virtualenvs/py3_shunyi_44/lib/python3.6/site-packages/django/core/handlers/exception.py", line 34, in inner
    response = get_response(request)
  File "/home/ubuntu/.virtualenvs/py3_shunyi_44/lib/python3.6/site-packages/django/core/handlers/base.py", line 115, in _get_response
    response = self.process_exception_by_middleware(e, request)
  File "/home/ubuntu/.virtualenvs/py3_shunyi_44/lib/python3.6/site-packages/django/core/handlers/base.py", line 113, in _get_response
    response = wrapped_callback(request, *callback_args, **callback_kwargs)
  File "/home/ubuntu/.virtualenvs/py3_shunyi_44/lib/python3.6/site-packages/django/views/generic/base.py", line 71, in view
    return self.dispatch(request, *args, **kwargs)
  File "/home/ubuntu/.virtualenvs/py3_shunyi_44/lib/python3.6/site-packages/django/views/generic/base.py", line 97, in dispatch
    return handler(request, *args, **kwargs)
TypeError: get() got an unexpected keyword argument 'username'
ERROR 2021-01-02 18:23:25,529 basehttp 154 "GET /usernames/itcast_01/count/ HTTP/1.1" 500 78782
ERROR 2021-01-02 18:23:45,508 log 228 Internal Server Error: /usernames/<username>/count/
Traceback (most recent call last):
  File "/home/ubuntu/.virtualenvs/py3_shunyi_44/lib/python3.6/site-packages/django/core/handlers/exception.py", line 34, in inner
    response = get_response(request)
  File "/home/ubuntu/.virtualenvs/py3_shunyi_44/lib/python3.6/site-packages/django/core/handlers/base.py", line 115, in _get_response
    response = self.process_exception_by_middleware(e, request)
  File "/home/ubuntu/.virtualenvs/py3_shunyi_44/lib/python3.6/site-packages/django/core/handlers/base.py", line 113, in _get_response
    response = wrapped_callback(request, *callback_args, **callback_kwargs)
  File "/home/ubuntu/.virtualenvs/py3_shunyi_44/lib/python3.6/site-packages/django/views/generic/base.py", line 71, in view
    return self.dispatch(request, *args, **kwargs)
  File "/home/ubuntu/.virtualenvs/py3_shunyi_44/lib/python3.6/site-packages/django/views/generic/base.py", line 97, in dispatch
    return handler(request, *args, **kwargs)
TypeError: get() got an unexpected keyword argument 'username'
ERROR 2021-01-02 18:23:45,511 basehttp 154 "GET /usernames/%3Cusername%3E/count/ HTTP/1.1" 500 78811
ERROR 2021-01-02 18:27:26,395 log 228 Internal Server Error: /usernames/itcast/count/
Traceback (most recent call last):
  File "/home/ubuntu/.virtualenvs/py3_shunyi_44/lib/python3.6/site-packages/django/core/handlers/exception.py", line 34, in inner
    response = get_response(request)
  File "/home/ubuntu/.virtualenvs/py3_shunyi_44/lib/python3.6/site-packages/django/core/handlers/base.py", line 115, in _get_response
    response = self.process_exception_by_middleware(e, request)
  File "/home/ubuntu/.virtualenvs/py3_shunyi_44/lib/python3.6/site-packages/django/core/handlers/base.py", line 113, in _get_response
    response = wrapped_callback(request, *callback_args, **callback_kwargs)
  File "/home/ubuntu/.virtualenvs/py3_shunyi_44/lib/python3.6/site-packages/django/views/generic/base.py", line 71, in view
    return self.dispatch(request, *args, **kwargs)
  File "/home/ubuntu/.virtualenvs/py3_shunyi_44/lib/python3.6/site-packages/django/views/generic/base.py", line 97, in dispatch
    return handler(request, *args, **kwargs)
TypeError: get() got an unexpected keyword argument 'username'
ERROR 2021-01-02 18:27:26,403 basehttp 154 "GET /usernames/itcast/count/ HTTP/1.1" 500 78645
INFO 2021-01-02 18:28:28,895 autoreload 217 /home/ubuntu/Desktop/test/MeiDuo_test/meiduo_mail/apps/users/views.py changed, reloading.
INFO 2021-01-02 18:28:29,615 autoreload 597 Watching for file changes with StatReloader
INFO 2021-01-02 18:28:33,097 basehttp 154 "GET /usernames/itcast/count/ HTTP/1.1" 200 39
INFO 2021-01-02 18:32:03,323 autoreload 217 /home/ubuntu/Desktop/test/MeiDuo_test/meiduo_mail/apps/users/urls.py changed, reloading.
INFO 2021-01-02 18:32:03,725 autoreload 597 Watching for file changes with StatReloader
INFO 2021-01-02 18:36:55,943 autoreload 217 /home/ubuntu/Desktop/test/MeiDuo_test/meiduo_mail/meiduo_mail/urls.py changed, reloading.
INFO 2021-01-02 18:36:56,449 autoreload 597 Watching for file changes with StatReloader
INFO 2021-01-02 18:40:42,590 autoreload 217 /home/ubuntu/Desktop/test/MeiDuo_test/meiduo_mail/utils/converts.py changed, reloading.
INFO 2021-01-02 18:40:43,827 autoreload 597 Watching for file changes with StatReloader
INFO 2021-01-02 18:42:53,861 autoreload 217 /home/ubuntu/Desktop/test/MeiDuo_test/meiduo_mail/apps/users/urls.py changed, reloading.
INFO 2021-01-02 18:42:54,465 autoreload 597 Watching for file changes with StatReloader
INFO 2021-01-02 18:42:59,266 basehttp 154 "GET /usernames/itcast_01/count/ HTTP/1.1" 200 39
WARNING 2021-01-02 18:43:08,444 log 228 Not Found: /image_codes/f302fc1c-55df-4889-a78f-16869620c84e/
WARNING 2021-01-02 18:43:08,446 basehttp 154 "GET /image_codes/f302fc1c-55df-4889-a78f-16869620c84e/ HTTP/1.1" 404 2459
INFO 2021-01-02 18:43:20,988 basehttp 154 "GET /usernames/itcast_01/count/ HTTP/1.1" 200 39
INFO 2021-01-02 18:43:50,665 basehttp 154 "GET /usernames/itcast_01/count/ HTTP/1.1" 200 39
INFO 2021-01-02 18:47:26,568 autoreload 217 /home/ubuntu/Desktop/test/MeiDuo_test/meiduo_mail/apps/users/views.py changed, reloading.
INFO 2021-01-02 18:47:27,723 autoreload 597 Watching for file changes with StatReloader
INFO 2021-01-02 18:59:36,349 autoreload 217 /home/ubuntu/Desktop/test/MeiDuo_test/meiduo_mail/apps/users/views.py changed, reloading.
INFO 2021-01-02 18:59:37,111 autoreload 597 Watching for file changes with StatReloader
INFO 2021-01-02 19:10:44,874 autoreload 217 /home/ubuntu/Desktop/test/MeiDuo_test/meiduo_mail/apps/users/views.py changed, reloading.
INFO 2021-01-02 19:10:45,622 autoreload 597 Watching for file changes with StatReloader
WARNING 2021-01-02 19:10:59,231 log 228 Not Found: /image_codes/d8242b58-ccc4-4fbe-9b86-62e5a7692788/
WARNING 2021-01-02 19:10:59,232 basehttp 154 "GET /image_codes/d8242b58-ccc4-4fbe-9b86-62e5a7692788/ HTTP/1.1" 404 2615
WARNING 2021-01-02 19:11:07,349 log 228 Not Found: /image_codes/09274aff-d91c-4821-a972-6b2d870c6764/
WARNING 2021-01-02 19:11:07,350 basehttp 154 "GET /image_codes/09274aff-d91c-4821-a972-6b2d870c6764/ HTTP/1.1" 404 2615
WARNING 2021-01-02 19:12:33,284 log 228 Not Found: /search/
WARNING 2021-01-02 19:12:33,285 basehttp 154 "GET /search/?page=1&page_size=6 HTTP/1.1" 404 2512
INFO 2021-01-02 19:29:00,246 autoreload 217 /home/ubuntu/Desktop/test/MeiDuo_test/meiduo_mail/apps/users/views.py changed, reloading.
INFO 2021-01-02 19:29:01,161 autoreload 597 Watching for file changes with StatReloader
INFO 2021-01-02 19:29:38,144 autoreload 217 /home/ubuntu/Desktop/test/MeiDuo_test/meiduo_mail/apps/users/views.py changed, reloading.
INFO 2021-01-02 19:29:38,707 autoreload 597 Watching for file changes with StatReloader
INFO 2021-01-02 19:34:08,156 autoreload 217 /home/ubuntu/Desktop/test/MeiDuo_test/meiduo_mail/apps/users/views.py changed, reloading.
INFO 2021-01-02 19:34:09,368 autoreload 597 Watching for file changes with StatReloader
INFO 2021-01-02 19:36:06,132 autoreload 217 /home/ubuntu/Desktop/test/MeiDuo_test/meiduo_mail/apps/users/views.py changed, reloading.
INFO 2021-01-02 19:36:06,792 autoreload 597 Watching for file changes with StatReloader
INFO 2021-01-02 19:36:32,358 autoreload 217 /home/ubuntu/Desktop/test/MeiDuo_test/meiduo_mail/apps/users/views.py changed, reloading.
INFO 2021-01-02 19:36:32,782 autoreload 597 Watching for file changes with StatReloader
WARNING 2021-01-02 19:36:55,931 log 228 Not Found: /carts/simple/
WARNING 2021-01-02 19:36:55,933 basehttp 154 "GET /carts/simple/ HTTP/1.1" 404 2507
WARNING 2021-01-02 19:36:57,853 log 228 Not Found: /image_codes/6f844c76-a0bd-41ee-97aa-bf9c4b4bbcf5/
WARNING 2021-01-02 19:36:57,854 basehttp 154 "GET /image_codes/6f844c76-a0bd-41ee-97aa-bf9c4b4bbcf5/ HTTP/1.1" 404 2615
INFO 2021-01-02 19:36:58,928 basehttp 154 "GET /usernames/itcast_01/count/ HTTP/1.1" 200 39
INFO 2021-01-02 19:37:00,816 basehttp 154 "GET /usernames/itcast_01/count/ HTTP/1.1" 200 39
WARNING 2021-01-02 19:37:14,110 log 228 Not Found: /mobiles/15700000000/count/
WARNING 2021-01-02 19:37:14,113 basehttp 154 "GET /mobiles/15700000000/count/ HTTP/1.1" 404 2546
INFO 2021-01-02 19:37:20,414 basehttp 154 "GET /usernames/itcast_01/count/ HTTP/1.1" 200 39
WARNING 2021-01-02 19:37:20,417 log 228 Not Found: /mobiles/15700000000/count/
INFO 2021-01-02 19:37:20,419 basehttp 154 "OPTIONS /register/ HTTP/1.1" 200 0
WARNING 2021-01-02 19:37:20,420 basehttp 154 "GET /mobiles/15700000000/count/ HTTP/1.1" 404 2546
INFO 2021-01-02 19:37:20,619 basehttp 154 "POST /register/ HTTP/1.1" 200 27
WARNING 2021-01-02 19:37:21,148 log 228 Not Found: /carts/simple/
WARNING 2021-01-02 19:37:21,150 basehttp 154 "GET /carts/simple/ HTTP/1.1" 404 2507
INFO 2021-01-02 22:55:32,110 autoreload 597 Watching for file changes with StatReloader
WARNING 2021-01-02 22:55:34,768 log 228 Not Found: /mobiles/15700000001/count/
INFO 2021-01-02 22:55:34,778 basehttp 154 "GET /usernames/itcast_02/count/ HTTP/1.1" 200 39
WARNING 2021-01-02 22:55:34,782 basehttp 154 "GET /mobiles/15700000001/count/ HTTP/1.1" 404 2546
INFO 2021-01-02 22:55:34,961 basehttp 154 "POST /register/ HTTP/1.1" 200 27
WARNING 2021-01-02 22:55:36,127 log 228 Not Found: /carts/simple/
WARNING 2021-01-02 22:55:36,128 basehttp 154 "GET /carts/simple/ HTTP/1.1" 404 2507
INFO 2021-01-04 15:47:42,065 autoreload 597 Watching for file changes with StatReloader
WARNING 2021-01-04 15:48:03,814 log 228 Not Found: /image_code/axx-bxxx/
WARNING 2021-01-04 15:48:03,815 basehttp 154 "GET /image_code/axx-bxxx/ HTTP/1.1" 404 2705
WARNING 2021-01-04 15:48:03,935 log 228 Not Found: /favicon.ico
WARNING 2021-01-04 15:48:03,937 basehttp 154 "GET /favicon.ico HTTP/1.1" 404 2678
INFO 2021-01-04 15:48:13,920 basehttp 154 "GET /image_codes/axx-bxxx/ HTTP/1.1" 200 3051
INFO 2021-01-04 15:51:40,057 autoreload 217 /home/ubuntu/Desktop/test/day08/MeiDuo_test/meiduo_mail/apps/verifications/urls.py changed, reloading.
INFO 2021-01-04 15:51:40,691 autoreload 597 Watching for file changes with StatReloader
WARNING 2021-01-04 16:15:02,532 log 228 Not Found: /carts/simple/
WARNING 2021-01-04 16:15:02,534 basehttp 154 "GET /carts/simple/ HTTP/1.1" 404 2684
INFO 2021-01-04 16:15:03,492 basehttp 154 "GET /image_codes/6e65a40e-3701-4f84-9b92-affe1964f2db/ HTTP/1.1" 200 3243
INFO 2021-01-04 16:15:04,746 basehttp 154 "GET /usernames/itcast_01/count/ HTTP/1.1" 200 39
INFO 2021-01-04 16:15:04,795 basehttp 154 "GET /image_codes/959e3521-665c-46c1-81e1-555267fc8d9d/ HTTP/1.1" 200 3318
INFO 2021-01-04 16:15:05,416 basehttp 154 "GET /image_codes/d9f01d92-f31e-4258-8158-8e93d1d9f3a2/ HTTP/1.1" 200 3296
INFO 2021-01-04 16:15:05,819 basehttp 154 "GET /image_codes/d31a38ed-0270-4515-af0e-f2048435b40e/ HTTP/1.1" 200 2979
INFO 2021-01-04 16:15:06,200 basehttp 154 "GET /image_codes/4ccbc09c-744d-46ab-a12f-98397ee20c0e/ HTTP/1.1" 200 3474
INFO 2021-01-04 16:15:06,524 basehttp 154 "GET /image_codes/961ce346-40ae-434d-a3df-518cbfc4de52/ HTTP/1.1" 200 3071
INFO 2021-01-04 16:15:07,877 basehttp 154 "GET /image_codes/14a743cd-7daf-4f08-808f-ae315de0291d/ HTTP/1.1" 200 3014
INFO 2021-01-04 16:28:46,660 autoreload 217 /home/ubuntu/Desktop/test/day08/MeiDuo_test/meiduo_mail/apps/verifications/urls.py changed, reloading.
INFO 2021-01-04 16:28:47,620 autoreload 597 Watching for file changes with StatReloader
WARNING 2021-01-04 16:28:50,104 log 228 Not Found: /mobiles/15735404103/count/
WARNING 2021-01-04 16:28:50,105 basehttp 154 "GET /mobiles/15735404103/count/ HTTP/1.1" 404 2900
WARNING 2021-01-04 16:28:50,917 log 228 Not Found: /mobiles/15735404103/count/
WARNING 2021-01-04 16:28:50,918 basehttp 154 "GET /mobiles/15735404103/count/ HTTP/1.1" 404 2900
WARNING 2021-01-04 16:28:50,924 log 228 Not Found: /sms_codes/15735404103/
WARNING 2021-01-04 16:28:50,927 basehttp 154 "GET /sms_codes/15735404103/?image_code=&image_code_id=14a743cd-7daf-4f08-808f-ae315de0291d HTTP/1.1" 404 2955
WARNING 2021-01-04 16:28:53,428 log 228 Not Found: /mobiles/15735404103/count/
WARNING 2021-01-04 16:28:53,428 basehttp 154 "GET /mobiles/15735404103/count/ HTTP/1.1" 404 2900
WARNING 2021-01-04 16:28:53,437 log 228 Not Found: /sms_codes/15735404103/
WARNING 2021-01-04 16:28:53,437 basehttp 154 "GET /sms_codes/15735404103/?image_code=&image_code_id=14a743cd-7daf-4f08-808f-ae315de0291d HTTP/1.1" 404 2955
WARNING 2021-01-04 16:28:55,810 log 228 Not Found: /mobiles/15735404103/count/
WARNING 2021-01-04 16:28:55,813 log 228 Not Found: /sms_codes/15735404103/
WARNING 2021-01-04 16:28:55,814 basehttp 154 "GET /sms_codes/15735404103/?image_code=&image_code_id=14a743cd-7daf-4f08-808f-ae315de0291d HTTP/1.1" 404 2955
WARNING 2021-01-04 16:28:55,814 basehttp 154 "GET /mobiles/15735404103/count/ HTTP/1.1" 404 2900
WARNING 2021-01-04 16:28:58,999 log 228 Not Found: /mobiles/15735404103/count/
WARNING 2021-01-04 16:28:59,003 log 228 Not Found: /sms_codes/15735404103/
WARNING 2021-01-04 16:28:59,004 basehttp 154 "GET /sms_codes/15735404103/?image_code=123456&image_code_id=14a743cd-7daf-4f08-808f-ae315de0291d HTTP/1.1" 404 2961
WARNING 2021-01-04 16:28:59,004 basehttp 154 "GET /mobiles/15735404103/count/ HTTP/1.1" 404 2900
WARNING 2021-01-04 16:29:01,289 log 228 Not Found: /sms_codes/15735404103/
WARNING 2021-01-04 16:29:01,292 log 228 Not Found: /mobiles/15735404103/count/
WARNING 2021-01-04 16:29:01,293 basehttp 154 "GET /mobiles/15735404103/count/ HTTP/1.1" 404 2900
WARNING 2021-01-04 16:29:01,293 basehttp 154 "GET /sms_codes/15735404103/?image_code=123456&image_code_id=14a743cd-7daf-4f08-808f-ae315de0291d HTTP/1.1" 404 2961
WARNING 2021-01-04 16:29:04,404 log 228 Not Found: /mobiles/15735404103/count/
WARNING 2021-01-04 16:29:04,406 log 228 Not Found: /sms_codes/15735404103/
WARNING 2021-01-04 16:29:04,407 basehttp 154 "GET /sms_codes/15735404103/?image_code=123456&image_code_id=14a743cd-7daf-4f08-808f-ae315de0291d HTTP/1.1" 404 2961
WARNING 2021-01-04 16:29:04,407 basehttp 154 "GET /mobiles/15735404103/count/ HTTP/1.1" 404 2900
WARNING 2021-01-04 16:29:04,987 log 228 Not Found: /mobiles/15735404103/count/
WARNING 2021-01-04 16:29:04,990 basehttp 154 "GET /mobiles/15735404103/count/ HTTP/1.1" 404 2900
WARNING 2021-01-04 16:29:04,992 log 228 Not Found: /sms_codes/15735404103/
WARNING 2021-01-04 16:29:04,993 basehttp 154 "GET /sms_codes/15735404103/?image_code=123456&image_code_id=14a743cd-7daf-4f08-808f-ae315de0291d HTTP/1.1" 404 2961
WARNING 2021-01-04 16:29:05,727 log 228 Not Found: /sms_codes/15735404103/
WARNING 2021-01-04 16:29:05,730 log 228 Not Found: /mobiles/15735404103/count/
WARNING 2021-01-04 16:29:05,731 basehttp 154 "GET /sms_codes/15735404103/?image_code=123456&image_code_id=14a743cd-7daf-4f08-808f-ae315de0291d HTTP/1.1" 404 2961
WARNING 2021-01-04 16:29:05,732 basehttp 154 "GET /mobiles/15735404103/count/ HTTP/1.1" 404 2900
WARNING 2021-01-04 16:29:08,333 log 228 Not Found: /mobiles/15735404103/count/
WARNING 2021-01-04 16:29:08,335 log 228 Not Found: /sms_codes/15735404103/
WARNING 2021-01-04 16:29:08,336 basehttp 154 "GET /mobiles/15735404103/count/ HTTP/1.1" 404 2900
WARNING 2021-01-04 16:29:08,337 basehttp 154 "GET /sms_codes/15735404103/?image_code=123456&image_code_id=14a743cd-7daf-4f08-808f-ae315de0291d HTTP/1.1" 404 2961
WARNING 2021-01-04 16:29:09,980 log 228 Not Found: /mobiles/15735404103/count/
WARNING 2021-01-04 16:29:09,987 log 228 Not Found: /sms_codes/15735404103/
WARNING 2021-01-04 16:29:09,988 basehttp 154 "GET /sms_codes/15735404103/?image_code=123456&image_code_id=14a743cd-7daf-4f08-808f-ae315de0291d HTTP/1.1" 404 2961
WARNING 2021-01-04 16:29:09,989 basehttp 154 "GET /mobiles/15735404103/count/ HTTP/1.1" 404 2900
WARNING 2021-01-04 16:29:13,023 log 228 Not Found: /mobiles/15735404103/count/
WARNING 2021-01-04 16:29:13,026 basehttp 154 "GET /mobiles/15735404103/count/ HTTP/1.1" 404 2900
WARNING 2021-01-04 16:29:13,029 log 228 Not Found: /sms_codes/15735404103/
WARNING 2021-01-04 16:29:13,031 basehttp 154 "GET /sms_codes/15735404103/?image_code=123456&image_code_id=14a743cd-7daf-4f08-808f-ae315de0291d HTTP/1.1" 404 2961
INFO 2021-01-04 16:29:28,653 basehttp 154 "GET /image_codes/d120ea78-8634-4c34-a6cc-48589173f898/ HTTP/1.1" 200 3174
INFO 2021-01-04 16:29:28,940 basehttp 154 "GET /image_codes/a461c238-9796-4759-9321-780eb13d424e/ HTTP/1.1" 200 3060
INFO 2021-01-04 16:29:30,852 basehttp 154 "GET /image_codes/16125a4b-5125-4990-8aeb-1b9ad29fcc03/ HTTP/1.1" 200 3183
INFO 2021-01-04 16:29:32,964 basehttp 154 "GET /usernames/itcast_01/count/ HTTP/1.1" 200 39
WARNING 2021-01-04 16:29:35,122 log 228 Not Found: /mobiles/15735404103/count/
WARNING 2021-01-04 16:29:35,125 basehttp 154 "GET /mobiles/15735404103/count/ HTTP/1.1" 404 2900
WARNING 2021-01-04 16:29:36,688 log 228 Not Found: /sms_codes/15735404103/
WARNING 2021-01-04 16:29:36,690 log 228 Not Found: /mobiles/15735404103/count/
WARNING 2021-01-04 16:29:36,692 basehttp 154 "GET /mobiles/15735404103/count/ HTTP/1.1" 404 2900
WARNING 2021-01-04 16:29:36,693 basehttp 154 "GET /sms_codes/15735404103/?image_code=&image_code_id=16125a4b-5125-4990-8aeb-1b9ad29fcc03 HTTP/1.1" 404 2955
WARNING 2021-01-04 16:29:37,358 log 228 Not Found: /mobiles/15735404103/count/
WARNING 2021-01-04 16:29:37,360 log 228 Not Found: /sms_codes/15735404103/
WARNING 2021-01-04 16:29:37,361 basehttp 154 "GET /mobiles/15735404103/count/ HTTP/1.1" 404 2900
WARNING 2021-01-04 16:29:37,362 basehttp 154 "GET /sms_codes/15735404103/?image_code=&image_code_id=16125a4b-5125-4990-8aeb-1b9ad29fcc03 HTTP/1.1" 404 2955
WARNING 2021-01-04 16:29:38,081 log 228 Not Found: /mobiles/15735404103/count/
WARNING 2021-01-04 16:29:38,083 log 228 Not Found: /sms_codes/15735404103/
WARNING 2021-01-04 16:29:38,084 basehttp 154 "GET /mobiles/15735404103/count/ HTTP/1.1" 404 2900
WARNING 2021-01-04 16:29:38,085 basehttp 154 "GET /sms_codes/15735404103/?image_code=&image_code_id=16125a4b-5125-4990-8aeb-1b9ad29fcc03 HTTP/1.1" 404 2955
WARNING 2021-01-04 16:29:39,071 log 228 Not Found: /sms_codes/15735404103/
WARNING 2021-01-04 16:29:39,073 log 228 Not Found: /mobiles/15735404103/count/
WARNING 2021-01-04 16:29:39,074 basehttp 154 "GET /mobiles/15735404103/count/ HTTP/1.1" 404 2900
WARNING 2021-01-04 16:29:39,074 basehttp 154 "GET /sms_codes/15735404103/?image_code=&image_code_id=16125a4b-5125-4990-8aeb-1b9ad29fcc03 HTTP/1.1" 404 2955
WARNING 2021-01-04 16:29:39,236 log 228 Not Found: /sms_codes/15735404103/
WARNING 2021-01-04 16:29:39,238 log 228 Not Found: /mobiles/15735404103/count/
WARNING 2021-01-04 16:29:39,238 basehttp 154 "GET /sms_codes/15735404103/?image_code=&image_code_id=16125a4b-5125-4990-8aeb-1b9ad29fcc03 HTTP/1.1" 404 2955
WARNING 2021-01-04 16:29:39,240 basehttp 154 "GET /mobiles/15735404103/count/ HTTP/1.1" 404 2900
WARNING 2021-01-04 16:29:39,403 log 228 Not Found: /sms_codes/15735404103/
WARNING 2021-01-04 16:29:39,406 log 228 Not Found: /mobiles/15735404103/count/
WARNING 2021-01-04 16:29:39,407 basehttp 154 "GET /mobiles/15735404103/count/ HTTP/1.1" 404 2900
WARNING 2021-01-04 16:29:39,408 basehttp 154 "GET /sms_codes/15735404103/?image_code=&image_code_id=16125a4b-5125-4990-8aeb-1b9ad29fcc03 HTTP/1.1" 404 2955
WARNING 2021-01-04 16:29:39,551 log 228 Not Found: /mobiles/15735404103/count/
WARNING 2021-01-04 16:29:39,552 basehttp 154 "GET /mobiles/15735404103/count/ HTTP/1.1" 404 2900
WARNING 2021-01-04 16:29:39,555 log 228 Not Found: /sms_codes/15735404103/
WARNING 2021-01-04 16:29:39,555 basehttp 154 "GET /sms_codes/15735404103/?image_code=&image_code_id=16125a4b-5125-4990-8aeb-1b9ad29fcc03 HTTP/1.1" 404 2955
WARNING 2021-01-04 16:29:39,713 log 228 Not Found: /mobiles/15735404103/count/
WARNING 2021-01-04 16:29:39,717 basehttp 154 "GET /mobiles/15735404103/count/ HTTP/1.1" 404 2900
WARNING 2021-01-04 16:29:39,720 log 228 Not Found: /sms_codes/15735404103/
WARNING 2021-01-04 16:29:39,721 basehttp 154 "GET /sms_codes/15735404103/?image_code=&image_code_id=16125a4b-5125-4990-8aeb-1b9ad29fcc03 HTTP/1.1" 404 2955
WARNING 2021-01-04 16:29:39,941 log 228 Not Found: /sms_codes/15735404103/
WARNING 2021-01-04 16:29:39,943 log 228 Not Found: /mobiles/15735404103/count/
WARNING 2021-01-04 16:29:39,944 basehttp 154 "GET /sms_codes/15735404103/?image_code=&image_code_id=16125a4b-5125-4990-8aeb-1b9ad29fcc03 HTTP/1.1" 404 2955
WARNING 2021-01-04 16:29:39,945 basehttp 154 "GET /mobiles/15735404103/count/ HTTP/1.1" 404 2900
WARNING 2021-01-04 16:29:40,134 log 228 Not Found: /sms_codes/15735404103/
WARNING 2021-01-04 16:29:40,135 log 228 Not Found: /mobiles/15735404103/count/
WARNING 2021-01-04 16:29:40,137 basehttp 154 "GET /sms_codes/15735404103/?image_code=&image_code_id=16125a4b-5125-4990-8aeb-1b9ad29fcc03 HTTP/1.1" 404 2955
WARNING 2021-01-04 16:29:40,137 basehttp 154 "GET /mobiles/15735404103/count/ HTTP/1.1" 404 2900
INFO 2021-01-04 16:30:01,711 basehttp 154 "GET /image_codes/a4ca4fa7-1a79-4e1b-a919-863948abdc16/ HTTP/1.1" 200 3263
INFO 2021-01-04 16:30:07,059 basehttp 154 "GET /usernames/itcast_01/count/ HTTP/1.1" 200 39
WARNING 2021-01-04 16:30:17,036 log 228 Not Found: /mobiles/15735404103/count/
WARNING 2021-01-04 16:30:17,048 basehttp 154 "GET /mobiles/15735404103/count/ HTTP/1.1" 404 2900
WARNING 2021-01-04 16:30:17,140 log 228 Not Found: /mobiles/15735404103/count/
WARNING 2021-01-04 16:30:17,150 log 228 Not Found: /sms_codes/15735404103/
WARNING 2021-01-04 16:30:17,151 basehttp 154 "GET /mobiles/15735404103/count/ HTTP/1.1" 404 2900
WARNING 2021-01-04 16:30:17,152 basehttp 154 "GET /sms_codes/15735404103/?image_code=&image_code_id=a4ca4fa7-1a79-4e1b-a919-863948abdc16 HTTP/1.1" 404 2955
INFO 2021-01-04 16:32:41,216 autoreload 217 /home/ubuntu/Desktop/test/day08/MeiDuo_test/meiduo_mail/apps/verifications/urls.py changed, reloading.
INFO 2021-01-04 16:32:41,971 autoreload 597 Watching for file changes with StatReloader
INFO 2021-01-04 16:32:47,838 basehttp 154 "GET /image_codes/83b1c049-b15e-4c8e-a748-be46d2d53258/ HTTP/1.1" 200 3079
INFO 2021-01-04 16:32:49,371 basehttp 154 "GET /usernames/itcast_01/count/ HTTP/1.1" 200 39
WARNING 2021-01-04 16:32:52,479 log 228 Not Found: /mobiles/15735404103/count/
WARNING 2021-01-04 16:32:52,481 basehttp 154 "GET /mobiles/15735404103/count/ HTTP/1.1" 404 2895
WARNING 2021-01-04 16:32:52,532 log 228 Not Found: /mobiles/15735404103/count/
WARNING 2021-01-04 16:32:52,534 basehttp 154 "GET /mobiles/15735404103/count/ HTTP/1.1" 404 2895
INFO 2021-01-04 16:32:52,550 basehttp 154 "GET /sms_codes/15735404103/?image_code=&image_code_id=83b1c049-b15e-4c8e-a748-be46d2d53258 HTTP/1.1" 200 27
INFO 2021-01-04 16:38:55,683 autoreload 217 /home/ubuntu/Desktop/test/day08/MeiDuo_test/meiduo_mail/apps/verifications/views.py changed, reloading.
INFO 2021-01-04 16:38:56,217 autoreload 597 Watching for file changes with StatReloader
INFO 2021-01-04 16:39:05,096 basehttp 154 "GET /sms_codes/15735404103/?image_code=lugx&image_code_id=83b1c049-b15e-4c8e-a748-be46d2d53258 HTTP/1.1" 200 27
WARNING 2021-01-04 16:39:05,108 log 228 Not Found: /mobiles/15735404103/count/
WARNING 2021-01-04 16:39:05,110 basehttp 154 "GET /mobiles/15735404103/count/ HTTP/1.1" 404 2895
INFO 2021-01-04 16:53:58,051 autoreload 217 /home/ubuntu/Desktop/test/day08/MeiDuo_test/meiduo_mail/apps/verifications/views.py changed, reloading.
INFO 2021-01-04 16:53:58,749 autoreload 597 Watching for file changes with StatReloader
INFO 2021-01-04 16:54:39,839 autoreload 217 /home/ubuntu/Desktop/test/day08/MeiDuo_test/meiduo_mail/apps/verifications/views.py changed, reloading.
INFO 2021-01-04 16:54:40,418 autoreload 597 Watching for file changes with StatReloader
INFO 2021-01-04 16:54:44,039 basehttp 154 "GET /image_codes/45b6c439-a177-4f68-b772-b876e984a7b1/ HTTP/1.1" 200 2886
INFO 2021-01-04 16:54:45,481 basehttp 154 "GET /image_codes/194e0c83-62c3-476c-99ea-62fc2cea1b85/ HTTP/1.1" 200 3212
INFO 2021-01-04 17:14:29,813 autoreload 217 /home/ubuntu/Desktop/test/day08/MeiDuo_test/meiduo_mail/apps/verifications/views.py changed, reloading.
INFO 2021-01-04 17:14:30,697 autoreload 597 Watching for file changes with StatReloader
INFO 2021-01-04 17:47:53,074 autoreload 217 /home/ubuntu/Desktop/test/day08/MeiDuo_test/meiduo_mail/apps/verifications/views.py changed, reloading.
INFO 2021-01-04 17:47:53,713 autoreload 597 Watching for file changes with StatReloader
INFO 2021-01-04 17:54:18,275 autoreload 217 /home/ubuntu/Desktop/test/day08/MeiDuo_test/meiduo_mail/apps/verifications/views.py changed, reloading.
INFO 2021-01-04 17:54:18,959 autoreload 597 Watching for file changes with StatReloader
