INFO 2021-01-02 17:47:25,122 autoreload 597 Watching for file changes with StatReloader
INFO 2021-01-02 18:20:44,163 autoreload 597 Watching for file changes with StatReloader
WARNING 2021-01-02 18:21:01,969 log 228 Not Found: /usernames/1111111/count/
WARNING 2021-01-02 18:21:01,970 basehttp 154 "GET /usernames/1111111/count/ HTTP/1.1" 404 2201
WARNING 2021-01-02 18:21:02,066 log 228 Not Found: /favicon.ico
WARNING 2021-01-02 18:21:02,067 basehttp 154 "GET /favicon.ico HTTP/1.1" 404 2162
WARNING 2021-01-02 18:21:20,438 log 228 Not Found: /usernames/<username>/count/
WARNING 2021-01-02 18:21:20,445 basehttp 154 "GET /usernames/%3Cusername%3E/count/ HTTP/1.1" 404 2226
INFO 2021-01-02 18:21:33,620 autoreload 217 /home/ubuntu/Desktop/test/MeiDuo_test/meiduo_mail/apps/users/urls.py changed, reloading.
INFO 2021-01-02 18:21:34,333 autoreload 597 Watching for file changes with StatReloader
ERROR 2021-01-02 18:21:37,052 log 228 Internal Server Error: /usernames/<username>/count/
Traceback (most recent call last):
  File "/home/ubuntu/.virtualenvs/py3_shunyi_44/lib/python3.6/site-packages/django/core/handlers/exception.py", line 34, in inner
    response = get_response(request)
  File "/home/ubuntu/.virtualenvs/py3_shunyi_44/lib/python3.6/site-packages/django/core/handlers/base.py", line 115, in _get_response
    response = self.process_exception_by_middleware(e, request)
  File "/home/ubuntu/.virtualenvs/py3_shunyi_44/lib/python3.6/site-packages/django/core/handlers/base.py", line 113, in _get_response
    response = wrapped_callback(request, *callback_args, **callback_kwargs)
  File "/home/ubuntu/.virtualenvs/py3_shunyi_44/lib/python3.6/site-packages/django/views/generic/base.py", line 71, in view
    return self.dispatch(request, *args, **kwargs)
  File "/home/ubuntu/.virtualenvs/py3_shunyi_44/lib/python3.6/site-packages/django/views/generic/base.py", line 97, in dispatch
    return handler(request, *args, **kwargs)
TypeError: get() got an unexpected keyword argument 'username'
ERROR 2021-01-02 18:21:37,054 basehttp 154 "GET /usernames/%3Cusername%3E/count/ HTTP/1.1" 500 78946
ERROR 2021-01-02 18:21:42,581 log 228 Internal Server Error: /usernames/111/count/
Traceback (most recent call last):
  File "/home/ubuntu/.virtualenvs/py3_shunyi_44/lib/python3.6/site-packages/django/core/handlers/exception.py", line 34, in inner
    response = get_response(request)
  File "/home/ubuntu/.virtualenvs/py3_shunyi_44/lib/python3.6/site-packages/django/core/handlers/base.py", line 115, in _get_response
    response = self.process_exception_by_middleware(e, request)
  File "/home/ubuntu/.virtualenvs/py3_shunyi_44/lib/python3.6/site-packages/django/core/handlers/base.py", line 113, in _get_response
    response = wrapped_callback(request, *callback_args, **callback_kwargs)
  File "/home/ubuntu/.virtualenvs/py3_shunyi_44/lib/python3.6/site-packages/django/views/generic/base.py", line 71, in view
    return self.dispatch(request, *args, **kwargs)
  File "/home/ubuntu/.virtualenvs/py3_shunyi_44/lib/python3.6/site-packages/django/views/generic/base.py", line 97, in dispatch
    return handler(request, *args, **kwargs)
TypeError: get() got an unexpected keyword argument 'username'
ERROR 2021-01-02 18:21:42,582 basehttp 154 "GET /usernames/111/count/ HTTP/1.1" 500 78591
ERROR 2021-01-02 18:21:57,016 log 228 Internal Server Error: /usernames/<username>/count/
Traceback (most recent call last):
  File "/home/ubuntu/.virtualenvs/py3_shunyi_44/lib/python3.6/site-packages/django/core/handlers/exception.py", line 34, in inner
    response = get_response(request)
  File "/home/ubuntu/.virtualenvs/py3_shunyi_44/lib/python3.6/site-packages/django/core/handlers/base.py", line 115, in _get_response
    response = self.process_exception_by_middleware(e, request)
  File "/home/ubuntu/.virtualenvs/py3_shunyi_44/lib/python3.6/site-packages/django/core/handlers/base.py", line 113, in _get_response
    response = wrapped_callback(request, *callback_args, **callback_kwargs)
  File "/home/ubuntu/.virtualenvs/py3_shunyi_44/lib/python3.6/site-packages/django/views/generic/base.py", line 71, in view
    return self.dispatch(request, *args, **kwargs)
  File "/home/ubuntu/.virtualenvs/py3_shunyi_44/lib/python3.6/site-packages/django/views/generic/base.py", line 97, in dispatch
    return handler(request, *args, **kwargs)
TypeError: get() got an unexpected keyword argument 'username'
ERROR 2021-01-02 18:21:57,017 basehttp 154 "GET /usernames/%3Cusername%3E/count/ HTTP/1.1" 500 78811
WARNING 2021-01-02 18:22:44,014 log 228 Not Found: /
WARNING 2021-01-02 18:22:44,015 basehttp 154 "GET / HTTP/1.1" 404 2112
WARNING 2021-01-02 18:23:02,126 log 228 Not Found: /image_codes/5219f997-deb2-4a68-a808-aadc59cf3aae/
WARNING 2021-01-02 18:23:02,126 basehttp 154 "GET /image_codes/5219f997-deb2-4a68-a808-aadc59cf3aae/ HTTP/1.1" 404 2277
ERROR 2021-01-02 18:23:03,394 log 228 Internal Server Error: /usernames/itcast_01/count/
Traceback (most recent call last):
  File "/home/ubuntu/.virtualenvs/py3_shunyi_44/lib/python3.6/site-packages/django/core/handlers/exception.py", line 34, in inner
    response = get_response(request)
  File "/home/ubuntu/.virtualenvs/py3_shunyi_44/lib/python3.6/site-packages/django/core/handlers/base.py", line 115, in _get_response
    response = self.process_exception_by_middleware(e, request)
  File "/home/ubuntu/.virtualenvs/py3_shunyi_44/lib/python3.6/site-packages/django/core/handlers/base.py", line 113, in _get_response
    response = wrapped_callback(request, *callback_args, **callback_kwargs)
  File "/home/ubuntu/.virtualenvs/py3_shunyi_44/lib/python3.6/site-packages/django/views/generic/base.py", line 71, in view
    return self.dispatch(request, *args, **kwargs)
  File "/home/ubuntu/.virtualenvs/py3_shunyi_44/lib/python3.6/site-packages/django/views/generic/base.py", line 97, in dispatch
    return handler(request, *args, **kwargs)
TypeError: get() got an unexpected keyword argument 'username'
ERROR 2021-01-02 18:23:03,406 basehttp 154 "GET /usernames/itcast_01/count/ HTTP/1.1" 500 78782
ERROR 2021-01-02 18:23:04,114 log 228 Internal Server Error: /usernames/itcast_01/count/
Traceback (most recent call last):
  File "/home/ubuntu/.virtualenvs/py3_shunyi_44/lib/python3.6/site-packages/django/core/handlers/exception.py", line 34, in inner
    response = get_response(request)
  File "/home/ubuntu/.virtualenvs/py3_shunyi_44/lib/python3.6/site-packages/django/core/handlers/base.py", line 115, in _get_response
    response = self.process_exception_by_middleware(e, request)
  File "/home/ubuntu/.virtualenvs/py3_shunyi_44/lib/python3.6/site-packages/django/core/handlers/base.py", line 113, in _get_response
    response = wrapped_callback(request, *callback_args, **callback_kwargs)
  File "/home/ubuntu/.virtualenvs/py3_shunyi_44/lib/python3.6/site-packages/django/views/generic/base.py", line 71, in view
    return self.dispatch(request, *args, **kwargs)
  File "/home/ubuntu/.virtualenvs/py3_shunyi_44/lib/python3.6/site-packages/django/views/generic/base.py", line 97, in dispatch
    return handler(request, *args, **kwargs)
TypeError: get() got an unexpected keyword argument 'username'
ERROR 2021-01-02 18:23:04,116 basehttp 154 "GET /usernames/itcast_01/count/ HTTP/1.1" 500 78782
ERROR 2021-01-02 18:23:06,714 log 228 Internal Server Error: /usernames/itcast_01/count/
Traceback (most recent call last):
  File "/home/ubuntu/.virtualenvs/py3_shunyi_44/lib/python3.6/site-packages/django/core/handlers/exception.py", line 34, in inner
    response = get_response(request)
  File "/home/ubuntu/.virtualenvs/py3_shunyi_44/lib/python3.6/site-packages/django/core/handlers/base.py", line 115, in _get_response
    response = self.process_exception_by_middleware(e, request)
  File "/home/ubuntu/.virtualenvs/py3_shunyi_44/lib/python3.6/site-packages/django/core/handlers/base.py", line 113, in _get_response
    response = wrapped_callback(request, *callback_args, **callback_kwargs)
  File "/home/ubuntu/.virtualenvs/py3_shunyi_44/lib/python3.6/site-packages/django/views/generic/base.py", line 71, in view
    return self.dispatch(request, *args, **kwargs)
  File "/home/ubuntu/.virtualenvs/py3_shunyi_44/lib/python3.6/site-packages/django/views/generic/base.py", line 97, in dispatch
    return handler(request, *args, **kwargs)
TypeError: get() got an unexpected keyword argument 'username'
ERROR 2021-01-02 18:23:06,717 basehttp 154 "GET /usernames/itcast_01/count/ HTTP/1.1" 500 78782
ERROR 2021-01-02 18:23:07,256 log 228 Internal Server Error: /usernames/itcast_01/count/
Traceback (most recent call last):
  File "/home/ubuntu/.virtualenvs/py3_shunyi_44/lib/python3.6/site-packages/django/core/handlers/exception.py", line 34, in inner
    response = get_response(request)
  File "/home/ubuntu/.virtualenvs/py3_shunyi_44/lib/python3.6/site-packages/django/core/handlers/base.py", line 115, in _get_response
    response = self.process_exception_by_middleware(e, request)
  File "/home/ubuntu/.virtualenvs/py3_shunyi_44/lib/python3.6/site-packages/django/core/handlers/base.py", line 113, in _get_response
    response = wrapped_callback(request, *callback_args, **callback_kwargs)
  File "/home/ubuntu/.virtualenvs/py3_shunyi_44/lib/python3.6/site-packages/django/views/generic/base.py", line 71, in view
    return self.dispatch(request, *args, **kwargs)
  File "/home/ubuntu/.virtualenvs/py3_shunyi_44/lib/python3.6/site-packages/django/views/generic/base.py", line 97, in dispatch
    return handler(request, *args, **kwargs)
TypeError: get() got an unexpected keyword argument 'username'
ERROR 2021-01-02 18:23:07,262 basehttp 154 "GET /usernames/itcast_01/count/ HTTP/1.1" 500 78782
ERROR 2021-01-02 18:23:08,427 log 228 Internal Server Error: /usernames/itcast_01/count/
Traceback (most recent call last):
  File "/home/ubuntu/.virtualenvs/py3_shunyi_44/lib/python3.6/site-packages/django/core/handlers/exception.py", line 34, in inner
    response = get_response(request)
  File "/home/ubuntu/.virtualenvs/py3_shunyi_44/lib/python3.6/site-packages/django/core/handlers/base.py", line 115, in _get_response
    response = self.process_exception_by_middleware(e, request)
  File "/home/ubuntu/.virtualenvs/py3_shunyi_44/lib/python3.6/site-packages/django/core/handlers/base.py", line 113, in _get_response
    response = wrapped_callback(request, *callback_args, **callback_kwargs)
  File "/home/ubuntu/.virtualenvs/py3_shunyi_44/lib/python3.6/site-packages/django/views/generic/base.py", line 71, in view
    return self.dispatch(request, *args, **kwargs)
  File "/home/ubuntu/.virtualenvs/py3_shunyi_44/lib/python3.6/site-packages/django/views/generic/base.py", line 97, in dispatch
    return handler(request, *args, **kwargs)
TypeError: get() got an unexpected keyword argument 'username'
ERROR 2021-01-02 18:23:08,428 basehttp 154 "GET /usernames/itcast_01/count/ HTTP/1.1" 500 78782
ERROR 2021-01-02 18:23:14,252 log 228 Internal Server Error: /usernames/itcast_01/count/
Traceback (most recent call last):
  File "/home/ubuntu/.virtualenvs/py3_shunyi_44/lib/python3.6/site-packages/django/core/handlers/exception.py", line 34, in inner
    response = get_response(request)
  File "/home/ubuntu/.virtualenvs/py3_shunyi_44/lib/python3.6/site-packages/django/core/handlers/base.py", line 115, in _get_response
    response = self.process_exception_by_middleware(e, request)
  File "/home/ubuntu/.virtualenvs/py3_shunyi_44/lib/python3.6/site-packages/django/core/handlers/base.py", line 113, in _get_response
    response = wrapped_callback(request, *callback_args, **callback_kwargs)
  File "/home/ubuntu/.virtualenvs/py3_shunyi_44/lib/python3.6/site-packages/django/views/generic/base.py", line 71, in view
    return self.dispatch(request, *args, **kwargs)
  File "/home/ubuntu/.virtualenvs/py3_shunyi_44/lib/python3.6/site-packages/django/views/generic/base.py", line 97, in dispatch
    return handler(request, *args, **kwargs)
TypeError: get() got an unexpected keyword argument 'username'
ERROR 2021-01-02 18:23:14,253 basehttp 154 "GET /usernames/itcast_01/count/ HTTP/1.1" 500 78782
ERROR 2021-01-02 18:23:21,207 log 228 Internal Server Error: /usernames/itcast_01/count/
Traceback (most recent call last):
  File "/home/ubuntu/.virtualenvs/py3_shunyi_44/lib/python3.6/site-packages/django/core/handlers/exception.py", line 34, in inner
    response = get_response(request)
  File "/home/ubuntu/.virtualenvs/py3_shunyi_44/lib/python3.6/site-packages/django/core/handlers/base.py", line 115, in _get_response
    response = self.process_exception_by_middleware(e, request)
  File "/home/ubuntu/.virtualenvs/py3_shunyi_44/lib/python3.6/site-packages/django/core/handlers/base.py", line 113, in _get_response
    response = wrapped_callback(request, *callback_args, **callback_kwargs)
  File "/home/ubuntu/.virtualenvs/py3_shunyi_44/lib/python3.6/site-packages/django/views/generic/base.py", line 71, in view
    return self.dispatch(request, *args, **kwargs)
  File "/home/ubuntu/.virtualenvs/py3_shunyi_44/lib/python3.6/site-packages/django/views/generic/base.py", line 97, in dispatch
    return handler(request, *args, **kwargs)
TypeError: get() got an unexpected keyword argument 'username'
ERROR 2021-01-02 18:23:21,213 basehttp 154 "GET /usernames/itcast_01/count/ HTTP/1.1" 500 78782
ERROR 2021-01-02 18:23:22,757 log 228 Internal Server Error: /usernames/itcast_01/count/
Traceback (most recent call last):
  File "/home/ubuntu/.virtualenvs/py3_shunyi_44/lib/python3.6/site-packages/django/core/handlers/exception.py", line 34, in inner
    response = get_response(request)
  File "/home/ubuntu/.virtualenvs/py3_shunyi_44/lib/python3.6/site-packages/django/core/handlers/base.py", line 115, in _get_response
    response = self.process_exception_by_middleware(e, request)
  File "/home/ubuntu/.virtualenvs/py3_shunyi_44/lib/python3.6/site-packages/django/core/handlers/base.py", line 113, in _get_response
    response = wrapped_callback(request, *callback_args, **callback_kwargs)
  File "/home/ubuntu/.virtualenvs/py3_shunyi_44/lib/python3.6/site-packages/django/views/generic/base.py", line 71, in view
    return self.dispatch(request, *args, **kwargs)
  File "/home/ubuntu/.virtualenvs/py3_shunyi_44/lib/python3.6/site-packages/django/views/generic/base.py", line 97, in dispatch
    return handler(request, *args, **kwargs)
TypeError: get() got an unexpected keyword argument 'username'
ERROR 2021-01-02 18:23:22,760 basehttp 154 "GET /usernames/itcast_01/count/ HTTP/1.1" 500 78782
ERROR 2021-01-02 18:23:24,560 log 228 Internal Server Error: /usernames/itcast_01/count/
Traceback (most recent call last):
  File "/home/ubuntu/.virtualenvs/py3_shunyi_44/lib/python3.6/site-packages/django/core/handlers/exception.py", line 34, in inner
    response = get_response(request)
  File "/home/ubuntu/.virtualenvs/py3_shunyi_44/lib/python3.6/site-packages/django/core/handlers/base.py", line 115, in _get_response
    response = self.process_exception_by_middleware(e, request)
  File "/home/ubuntu/.virtualenvs/py3_shunyi_44/lib/python3.6/site-packages/django/core/handlers/base.py", line 113, in _get_response
    response = wrapped_callback(request, *callback_args, **callback_kwargs)
  File "/home/ubuntu/.virtualenvs/py3_shunyi_44/lib/python3.6/site-packages/django/views/generic/base.py", line 71, in view
    return self.dispatch(request, *args, **kwargs)
  File "/home/ubuntu/.virtualenvs/py3_shunyi_44/lib/python3.6/site-packages/django/views/generic/base.py", line 97, in dispatch
    return handler(request, *args, **kwargs)
TypeError: get() got an unexpected keyword argument 'username'
ERROR 2021-01-02 18:23:24,564 basehttp 154 "GET /usernames/itcast_01/count/ HTTP/1.1" 500 78782
ERROR 2021-01-02 18:23:25,521 log 228 Internal Server Error: /usernames/itcast_01/count/
Traceback (most recent call last):
  File "/home/ubuntu/.virtualenvs/py3_shunyi_44/lib/python3.6/site-packages/django/core/handlers/exception.py", line 34, in inner
    response = get_response(request)
  File "/home/ubuntu/.virtualenvs/py3_shunyi_44/lib/python3.6/site-packages/django/core/handlers/base.py", line 115, in _get_response
    response = self.process_exception_by_middleware(e, request)
  File "/home/ubuntu/.virtualenvs/py3_shunyi_44/lib/python3.6/site-packages/django/core/handlers/base.py", line 113, in _get_response
    response = wrapped_callback(request, *callback_args, **callback_kwargs)
  File "/home/ubuntu/.virtualenvs/py3_shunyi_44/lib/python3.6/site-packages/django/views/generic/base.py", line 71, in view
    return self.dispatch(request, *args, **kwargs)
  File "/home/ubuntu/.virtualenvs/py3_shunyi_44/lib/python3.6/site-packages/django/views/generic/base.py", line 97, in dispatch
    return handler(request, *args, **kwargs)
TypeError: get() got an unexpected keyword argument 'username'
ERROR 2021-01-02 18:23:25,529 basehttp 154 "GET /usernames/itcast_01/count/ HTTP/1.1" 500 78782
ERROR 2021-01-02 18:23:45,508 log 228 Internal Server Error: /usernames/<username>/count/
Traceback (most recent call last):
  File "/home/ubuntu/.virtualenvs/py3_shunyi_44/lib/python3.6/site-packages/django/core/handlers/exception.py", line 34, in inner
    response = get_response(request)
  File "/home/ubuntu/.virtualenvs/py3_shunyi_44/lib/python3.6/site-packages/django/core/handlers/base.py", line 115, in _get_response
    response = self.process_exception_by_middleware(e, request)
  File "/home/ubuntu/.virtualenvs/py3_shunyi_44/lib/python3.6/site-packages/django/core/handlers/base.py", line 113, in _get_response
    response = wrapped_callback(request, *callback_args, **callback_kwargs)
  File "/home/ubuntu/.virtualenvs/py3_shunyi_44/lib/python3.6/site-packages/django/views/generic/base.py", line 71, in view
    return self.dispatch(request, *args, **kwargs)
  File "/home/ubuntu/.virtualenvs/py3_shunyi_44/lib/python3.6/site-packages/django/views/generic/base.py", line 97, in dispatch
    return handler(request, *args, **kwargs)
TypeError: get() got an unexpected keyword argument 'username'
ERROR 2021-01-02 18:23:45,511 basehttp 154 "GET /usernames/%3Cusername%3E/count/ HTTP/1.1" 500 78811
ERROR 2021-01-02 18:27:26,395 log 228 Internal Server Error: /usernames/itcast/count/
Traceback (most recent call last):
  File "/home/ubuntu/.virtualenvs/py3_shunyi_44/lib/python3.6/site-packages/django/core/handlers/exception.py", line 34, in inner
    response = get_response(request)
  File "/home/ubuntu/.virtualenvs/py3_shunyi_44/lib/python3.6/site-packages/django/core/handlers/base.py", line 115, in _get_response
    response = self.process_exception_by_middleware(e, request)
  File "/home/ubuntu/.virtualenvs/py3_shunyi_44/lib/python3.6/site-packages/django/core/handlers/base.py", line 113, in _get_response
    response = wrapped_callback(request, *callback_args, **callback_kwargs)
  File "/home/ubuntu/.virtualenvs/py3_shunyi_44/lib/python3.6/site-packages/django/views/generic/base.py", line 71, in view
    return self.dispatch(request, *args, **kwargs)
  File "/home/ubuntu/.virtualenvs/py3_shunyi_44/lib/python3.6/site-packages/django/views/generic/base.py", line 97, in dispatch
    return handler(request, *args, **kwargs)
TypeError: get() got an unexpected keyword argument 'username'
ERROR 2021-01-02 18:27:26,403 basehttp 154 "GET /usernames/itcast/count/ HTTP/1.1" 500 78645
INFO 2021-01-02 18:28:28,895 autoreload 217 /home/ubuntu/Desktop/test/MeiDuo_test/meiduo_mail/apps/users/views.py changed, reloading.
INFO 2021-01-02 18:28:29,615 autoreload 597 Watching for file changes with StatReloader
INFO 2021-01-02 18:28:33,097 basehttp 154 "GET /usernames/itcast/count/ HTTP/1.1" 200 39
INFO 2021-01-02 18:32:03,323 autoreload 217 /home/ubuntu/Desktop/test/MeiDuo_test/meiduo_mail/apps/users/urls.py changed, reloading.
INFO 2021-01-02 18:32:03,725 autoreload 597 Watching for file changes with StatReloader
INFO 2021-01-02 18:36:55,943 autoreload 217 /home/ubuntu/Desktop/test/MeiDuo_test/meiduo_mail/meiduo_mail/urls.py changed, reloading.
INFO 2021-01-02 18:36:56,449 autoreload 597 Watching for file changes with StatReloader
INFO 2021-01-02 18:40:42,590 autoreload 217 /home/ubuntu/Desktop/test/MeiDuo_test/meiduo_mail/utils/converts.py changed, reloading.
INFO 2021-01-02 18:40:43,827 autoreload 597 Watching for file changes with StatReloader
INFO 2021-01-02 18:42:53,861 autoreload 217 /home/ubuntu/Desktop/test/MeiDuo_test/meiduo_mail/apps/users/urls.py changed, reloading.
INFO 2021-01-02 18:42:54,465 autoreload 597 Watching for file changes with StatReloader
INFO 2021-01-02 18:42:59,266 basehttp 154 "GET /usernames/itcast_01/count/ HTTP/1.1" 200 39
WARNING 2021-01-02 18:43:08,444 log 228 Not Found: /image_codes/f302fc1c-55df-4889-a78f-16869620c84e/
WARNING 2021-01-02 18:43:08,446 basehttp 154 "GET /image_codes/f302fc1c-55df-4889-a78f-16869620c84e/ HTTP/1.1" 404 2459
INFO 2021-01-02 18:43:20,988 basehttp 154 "GET /usernames/itcast_01/count/ HTTP/1.1" 200 39
INFO 2021-01-02 18:43:50,665 basehttp 154 "GET /usernames/itcast_01/count/ HTTP/1.1" 200 39
INFO 2021-01-02 18:47:26,568 autoreload 217 /home/ubuntu/Desktop/test/MeiDuo_test/meiduo_mail/apps/users/views.py changed, reloading.
INFO 2021-01-02 18:47:27,723 autoreload 597 Watching for file changes with StatReloader
INFO 2021-01-02 18:59:36,349 autoreload 217 /home/ubuntu/Desktop/test/MeiDuo_test/meiduo_mail/apps/users/views.py changed, reloading.
INFO 2021-01-02 18:59:37,111 autoreload 597 Watching for file changes with StatReloader
INFO 2021-01-02 19:10:44,874 autoreload 217 /home/ubuntu/Desktop/test/MeiDuo_test/meiduo_mail/apps/users/views.py changed, reloading.
INFO 2021-01-02 19:10:45,622 autoreload 597 Watching for file changes with StatReloader
WARNING 2021-01-02 19:10:59,231 log 228 Not Found: /image_codes/d8242b58-ccc4-4fbe-9b86-62e5a7692788/
WARNING 2021-01-02 19:10:59,232 basehttp 154 "GET /image_codes/d8242b58-ccc4-4fbe-9b86-62e5a7692788/ HTTP/1.1" 404 2615
WARNING 2021-01-02 19:11:07,349 log 228 Not Found: /image_codes/09274aff-d91c-4821-a972-6b2d870c6764/
WARNING 2021-01-02 19:11:07,350 basehttp 154 "GET /image_codes/09274aff-d91c-4821-a972-6b2d870c6764/ HTTP/1.1" 404 2615
WARNING 2021-01-02 19:12:33,284 log 228 Not Found: /search/
WARNING 2021-01-02 19:12:33,285 basehttp 154 "GET /search/?page=1&page_size=6 HTTP/1.1" 404 2512
INFO 2021-01-02 19:29:00,246 autoreload 217 /home/ubuntu/Desktop/test/MeiDuo_test/meiduo_mail/apps/users/views.py changed, reloading.
INFO 2021-01-02 19:29:01,161 autoreload 597 Watching for file changes with StatReloader
INFO 2021-01-02 19:29:38,144 autoreload 217 /home/ubuntu/Desktop/test/MeiDuo_test/meiduo_mail/apps/users/views.py changed, reloading.
INFO 2021-01-02 19:29:38,707 autoreload 597 Watching for file changes with StatReloader
INFO 2021-01-02 19:34:08,156 autoreload 217 /home/ubuntu/Desktop/test/MeiDuo_test/meiduo_mail/apps/users/views.py changed, reloading.
INFO 2021-01-02 19:34:09,368 autoreload 597 Watching for file changes with StatReloader
INFO 2021-01-02 19:36:06,132 autoreload 217 /home/ubuntu/Desktop/test/MeiDuo_test/meiduo_mail/apps/users/views.py changed, reloading.
INFO 2021-01-02 19:36:06,792 autoreload 597 Watching for file changes with StatReloader
INFO 2021-01-02 19:36:32,358 autoreload 217 /home/ubuntu/Desktop/test/MeiDuo_test/meiduo_mail/apps/users/views.py changed, reloading.
INFO 2021-01-02 19:36:32,782 autoreload 597 Watching for file changes with StatReloader
WARNING 2021-01-02 19:36:55,931 log 228 Not Found: /carts/simple/
WARNING 2021-01-02 19:36:55,933 basehttp 154 "GET /carts/simple/ HTTP/1.1" 404 2507
WARNING 2021-01-02 19:36:57,853 log 228 Not Found: /image_codes/6f844c76-a0bd-41ee-97aa-bf9c4b4bbcf5/
WARNING 2021-01-02 19:36:57,854 basehttp 154 "GET /image_codes/6f844c76-a0bd-41ee-97aa-bf9c4b4bbcf5/ HTTP/1.1" 404 2615
INFO 2021-01-02 19:36:58,928 basehttp 154 "GET /usernames/itcast_01/count/ HTTP/1.1" 200 39
INFO 2021-01-02 19:37:00,816 basehttp 154 "GET /usernames/itcast_01/count/ HTTP/1.1" 200 39
WARNING 2021-01-02 19:37:14,110 log 228 Not Found: /mobiles/15700000000/count/
WARNING 2021-01-02 19:37:14,113 basehttp 154 "GET /mobiles/15700000000/count/ HTTP/1.1" 404 2546
INFO 2021-01-02 19:37:20,414 basehttp 154 "GET /usernames/itcast_01/count/ HTTP/1.1" 200 39
WARNING 2021-01-02 19:37:20,417 log 228 Not Found: /mobiles/15700000000/count/
INFO 2021-01-02 19:37:20,419 basehttp 154 "OPTIONS /register/ HTTP/1.1" 200 0
WARNING 2021-01-02 19:37:20,420 basehttp 154 "GET /mobiles/15700000000/count/ HTTP/1.1" 404 2546
INFO 2021-01-02 19:37:20,619 basehttp 154 "POST /register/ HTTP/1.1" 200 27
WARNING 2021-01-02 19:37:21,148 log 228 Not Found: /carts/simple/
WARNING 2021-01-02 19:37:21,150 basehttp 154 "GET /carts/simple/ HTTP/1.1" 404 2507
INFO 2021-01-02 22:55:32,110 autoreload 597 Watching for file changes with StatReloader
WARNING 2021-01-02 22:55:34,768 log 228 Not Found: /mobiles/15700000001/count/
INFO 2021-01-02 22:55:34,778 basehttp 154 "GET /usernames/itcast_02/count/ HTTP/1.1" 200 39
WARNING 2021-01-02 22:55:34,782 basehttp 154 "GET /mobiles/15700000001/count/ HTTP/1.1" 404 2546
INFO 2021-01-02 22:55:34,961 basehttp 154 "POST /register/ HTTP/1.1" 200 27
WARNING 2021-01-02 22:55:36,127 log 228 Not Found: /carts/simple/
WARNING 2021-01-02 22:55:36,128 basehttp 154 "GET /carts/simple/ HTTP/1.1" 404 2507
INFO 2021-01-04 15:47:42,065 autoreload 597 Watching for file changes with StatReloader
WARNING 2021-01-04 15:48:03,814 log 228 Not Found: /image_code/axx-bxxx/
WARNING 2021-01-04 15:48:03,815 basehttp 154 "GET /image_code/axx-bxxx/ HTTP/1.1" 404 2705
WARNING 2021-01-04 15:48:03,935 log 228 Not Found: /favicon.ico
WARNING 2021-01-04 15:48:03,937 basehttp 154 "GET /favicon.ico HTTP/1.1" 404 2678
INFO 2021-01-04 15:48:13,920 basehttp 154 "GET /image_codes/axx-bxxx/ HTTP/1.1" 200 3051
INFO 2021-01-04 15:51:40,057 autoreload 217 /home/ubuntu/Desktop/test/day08/MeiDuo_test/meiduo_mail/apps/verifications/urls.py changed, reloading.
INFO 2021-01-04 15:51:40,691 autoreload 597 Watching for file changes with StatReloader
WARNING 2021-01-04 16:15:02,532 log 228 Not Found: /carts/simple/
WARNING 2021-01-04 16:15:02,534 basehttp 154 "GET /carts/simple/ HTTP/1.1" 404 2684
INFO 2021-01-04 16:15:03,492 basehttp 154 "GET /image_codes/6e65a40e-3701-4f84-9b92-affe1964f2db/ HTTP/1.1" 200 3243
INFO 2021-01-04 16:15:04,746 basehttp 154 "GET /usernames/itcast_01/count/ HTTP/1.1" 200 39
INFO 2021-01-04 16:15:04,795 basehttp 154 "GET /image_codes/959e3521-665c-46c1-81e1-555267fc8d9d/ HTTP/1.1" 200 3318
INFO 2021-01-04 16:15:05,416 basehttp 154 "GET /image_codes/d9f01d92-f31e-4258-8158-8e93d1d9f3a2/ HTTP/1.1" 200 3296
INFO 2021-01-04 16:15:05,819 basehttp 154 "GET /image_codes/d31a38ed-0270-4515-af0e-f2048435b40e/ HTTP/1.1" 200 2979
INFO 2021-01-04 16:15:06,200 basehttp 154 "GET /image_codes/4ccbc09c-744d-46ab-a12f-98397ee20c0e/ HTTP/1.1" 200 3474
INFO 2021-01-04 16:15:06,524 basehttp 154 "GET /image_codes/961ce346-40ae-434d-a3df-518cbfc4de52/ HTTP/1.1" 200 3071
INFO 2021-01-04 16:15:07,877 basehttp 154 "GET /image_codes/14a743cd-7daf-4f08-808f-ae315de0291d/ HTTP/1.1" 200 3014
INFO 2021-01-04 16:28:46,660 autoreload 217 /home/ubuntu/Desktop/test/day08/MeiDuo_test/meiduo_mail/apps/verifications/urls.py changed, reloading.
INFO 2021-01-04 16:28:47,620 autoreload 597 Watching for file changes with StatReloader
WARNING 2021-01-04 16:28:50,104 log 228 Not Found: /mobiles/15735404103/count/
WARNING 2021-01-04 16:28:50,105 basehttp 154 "GET /mobiles/15735404103/count/ HTTP/1.1" 404 2900
WARNING 2021-01-04 16:28:50,917 log 228 Not Found: /mobiles/15735404103/count/
WARNING 2021-01-04 16:28:50,918 basehttp 154 "GET /mobiles/15735404103/count/ HTTP/1.1" 404 2900
WARNING 2021-01-04 16:28:50,924 log 228 Not Found: /sms_codes/15735404103/
WARNING 2021-01-04 16:28:50,927 basehttp 154 "GET /sms_codes/15735404103/?image_code=&image_code_id=14a743cd-7daf-4f08-808f-ae315de0291d HTTP/1.1" 404 2955
WARNING 2021-01-04 16:28:53,428 log 228 Not Found: /mobiles/15735404103/count/
WARNING 2021-01-04 16:28:53,428 basehttp 154 "GET /mobiles/15735404103/count/ HTTP/1.1" 404 2900
WARNING 2021-01-04 16:28:53,437 log 228 Not Found: /sms_codes/15735404103/
WARNING 2021-01-04 16:28:53,437 basehttp 154 "GET /sms_codes/15735404103/?image_code=&image_code_id=14a743cd-7daf-4f08-808f-ae315de0291d HTTP/1.1" 404 2955
WARNING 2021-01-04 16:28:55,810 log 228 Not Found: /mobiles/15735404103/count/
WARNING 2021-01-04 16:28:55,813 log 228 Not Found: /sms_codes/15735404103/
WARNING 2021-01-04 16:28:55,814 basehttp 154 "GET /sms_codes/15735404103/?image_code=&image_code_id=14a743cd-7daf-4f08-808f-ae315de0291d HTTP/1.1" 404 2955
WARNING 2021-01-04 16:28:55,814 basehttp 154 "GET /mobiles/15735404103/count/ HTTP/1.1" 404 2900
WARNING 2021-01-04 16:28:58,999 log 228 Not Found: /mobiles/15735404103/count/
WARNING 2021-01-04 16:28:59,003 log 228 Not Found: /sms_codes/15735404103/
WARNING 2021-01-04 16:28:59,004 basehttp 154 "GET /sms_codes/15735404103/?image_code=123456&image_code_id=14a743cd-7daf-4f08-808f-ae315de0291d HTTP/1.1" 404 2961
WARNING 2021-01-04 16:28:59,004 basehttp 154 "GET /mobiles/15735404103/count/ HTTP/1.1" 404 2900
WARNING 2021-01-04 16:29:01,289 log 228 Not Found: /sms_codes/15735404103/
WARNING 2021-01-04 16:29:01,292 log 228 Not Found: /mobiles/15735404103/count/
WARNING 2021-01-04 16:29:01,293 basehttp 154 "GET /mobiles/15735404103/count/ HTTP/1.1" 404 2900
WARNING 2021-01-04 16:29:01,293 basehttp 154 "GET /sms_codes/15735404103/?image_code=123456&image_code_id=14a743cd-7daf-4f08-808f-ae315de0291d HTTP/1.1" 404 2961
WARNING 2021-01-04 16:29:04,404 log 228 Not Found: /mobiles/15735404103/count/
WARNING 2021-01-04 16:29:04,406 log 228 Not Found: /sms_codes/15735404103/
WARNING 2021-01-04 16:29:04,407 basehttp 154 "GET /sms_codes/15735404103/?image_code=123456&image_code_id=14a743cd-7daf-4f08-808f-ae315de0291d HTTP/1.1" 404 2961
WARNING 2021-01-04 16:29:04,407 basehttp 154 "GET /mobiles/15735404103/count/ HTTP/1.1" 404 2900
WARNING 2021-01-04 16:29:04,987 log 228 Not Found: /mobiles/15735404103/count/
WARNING 2021-01-04 16:29:04,990 basehttp 154 "GET /mobiles/15735404103/count/ HTTP/1.1" 404 2900
WARNING 2021-01-04 16:29:04,992 log 228 Not Found: /sms_codes/15735404103/
WARNING 2021-01-04 16:29:04,993 basehttp 154 "GET /sms_codes/15735404103/?image_code=123456&image_code_id=14a743cd-7daf-4f08-808f-ae315de0291d HTTP/1.1" 404 2961
WARNING 2021-01-04 16:29:05,727 log 228 Not Found: /sms_codes/15735404103/
WARNING 2021-01-04 16:29:05,730 log 228 Not Found: /mobiles/15735404103/count/
WARNING 2021-01-04 16:29:05,731 basehttp 154 "GET /sms_codes/15735404103/?image_code=123456&image_code_id=14a743cd-7daf-4f08-808f-ae315de0291d HTTP/1.1" 404 2961
WARNING 2021-01-04 16:29:05,732 basehttp 154 "GET /mobiles/15735404103/count/ HTTP/1.1" 404 2900
WARNING 2021-01-04 16:29:08,333 log 228 Not Found: /mobiles/15735404103/count/
WARNING 2021-01-04 16:29:08,335 log 228 Not Found: /sms_codes/15735404103/
WARNING 2021-01-04 16:29:08,336 basehttp 154 "GET /mobiles/15735404103/count/ HTTP/1.1" 404 2900
WARNING 2021-01-04 16:29:08,337 basehttp 154 "GET /sms_codes/15735404103/?image_code=123456&image_code_id=14a743cd-7daf-4f08-808f-ae315de0291d HTTP/1.1" 404 2961
WARNING 2021-01-04 16:29:09,980 log 228 Not Found: /mobiles/15735404103/count/
WARNING 2021-01-04 16:29:09,987 log 228 Not Found: /sms_codes/15735404103/
WARNING 2021-01-04 16:29:09,988 basehttp 154 "GET /sms_codes/15735404103/?image_code=123456&image_code_id=14a743cd-7daf-4f08-808f-ae315de0291d HTTP/1.1" 404 2961
WARNING 2021-01-04 16:29:09,989 basehttp 154 "GET /mobiles/15735404103/count/ HTTP/1.1" 404 2900
WARNING 2021-01-04 16:29:13,023 log 228 Not Found: /mobiles/15735404103/count/
WARNING 2021-01-04 16:29:13,026 basehttp 154 "GET /mobiles/15735404103/count/ HTTP/1.1" 404 2900
WARNING 2021-01-04 16:29:13,029 log 228 Not Found: /sms_codes/15735404103/
WARNING 2021-01-04 16:29:13,031 basehttp 154 "GET /sms_codes/15735404103/?image_code=123456&image_code_id=14a743cd-7daf-4f08-808f-ae315de0291d HTTP/1.1" 404 2961
INFO 2021-01-04 16:29:28,653 basehttp 154 "GET /image_codes/d120ea78-8634-4c34-a6cc-48589173f898/ HTTP/1.1" 200 3174
INFO 2021-01-04 16:29:28,940 basehttp 154 "GET /image_codes/a461c238-9796-4759-9321-780eb13d424e/ HTTP/1.1" 200 3060
INFO 2021-01-04 16:29:30,852 basehttp 154 "GET /image_codes/16125a4b-5125-4990-8aeb-1b9ad29fcc03/ HTTP/1.1" 200 3183
INFO 2021-01-04 16:29:32,964 basehttp 154 "GET /usernames/itcast_01/count/ HTTP/1.1" 200 39
WARNING 2021-01-04 16:29:35,122 log 228 Not Found: /mobiles/15735404103/count/
WARNING 2021-01-04 16:29:35,125 basehttp 154 "GET /mobiles/15735404103/count/ HTTP/1.1" 404 2900
WARNING 2021-01-04 16:29:36,688 log 228 Not Found: /sms_codes/15735404103/
WARNING 2021-01-04 16:29:36,690 log 228 Not Found: /mobiles/15735404103/count/
WARNING 2021-01-04 16:29:36,692 basehttp 154 "GET /mobiles/15735404103/count/ HTTP/1.1" 404 2900
WARNING 2021-01-04 16:29:36,693 basehttp 154 "GET /sms_codes/15735404103/?image_code=&image_code_id=16125a4b-5125-4990-8aeb-1b9ad29fcc03 HTTP/1.1" 404 2955
WARNING 2021-01-04 16:29:37,358 log 228 Not Found: /mobiles/15735404103/count/
WARNING 2021-01-04 16:29:37,360 log 228 Not Found: /sms_codes/15735404103/
WARNING 2021-01-04 16:29:37,361 basehttp 154 "GET /mobiles/15735404103/count/ HTTP/1.1" 404 2900
WARNING 2021-01-04 16:29:37,362 basehttp 154 "GET /sms_codes/15735404103/?image_code=&image_code_id=16125a4b-5125-4990-8aeb-1b9ad29fcc03 HTTP/1.1" 404 2955
WARNING 2021-01-04 16:29:38,081 log 228 Not Found: /mobiles/15735404103/count/
WARNING 2021-01-04 16:29:38,083 log 228 Not Found: /sms_codes/15735404103/
WARNING 2021-01-04 16:29:38,084 basehttp 154 "GET /mobiles/15735404103/count/ HTTP/1.1" 404 2900
WARNING 2021-01-04 16:29:38,085 basehttp 154 "GET /sms_codes/15735404103/?image_code=&image_code_id=16125a4b-5125-4990-8aeb-1b9ad29fcc03 HTTP/1.1" 404 2955
WARNING 2021-01-04 16:29:39,071 log 228 Not Found: /sms_codes/15735404103/
WARNING 2021-01-04 16:29:39,073 log 228 Not Found: /mobiles/15735404103/count/
WARNING 2021-01-04 16:29:39,074 basehttp 154 "GET /mobiles/15735404103/count/ HTTP/1.1" 404 2900
WARNING 2021-01-04 16:29:39,074 basehttp 154 "GET /sms_codes/15735404103/?image_code=&image_code_id=16125a4b-5125-4990-8aeb-1b9ad29fcc03 HTTP/1.1" 404 2955
WARNING 2021-01-04 16:29:39,236 log 228 Not Found: /sms_codes/15735404103/
WARNING 2021-01-04 16:29:39,238 log 228 Not Found: /mobiles/15735404103/count/
WARNING 2021-01-04 16:29:39,238 basehttp 154 "GET /sms_codes/15735404103/?image_code=&image_code_id=16125a4b-5125-4990-8aeb-1b9ad29fcc03 HTTP/1.1" 404 2955
WARNING 2021-01-04 16:29:39,240 basehttp 154 "GET /mobiles/15735404103/count/ HTTP/1.1" 404 2900
WARNING 2021-01-04 16:29:39,403 log 228 Not Found: /sms_codes/15735404103/
WARNING 2021-01-04 16:29:39,406 log 228 Not Found: /mobiles/15735404103/count/
WARNING 2021-01-04 16:29:39,407 basehttp 154 "GET /mobiles/15735404103/count/ HTTP/1.1" 404 2900
WARNING 2021-01-04 16:29:39,408 basehttp 154 "GET /sms_codes/15735404103/?image_code=&image_code_id=16125a4b-5125-4990-8aeb-1b9ad29fcc03 HTTP/1.1" 404 2955
WARNING 2021-01-04 16:29:39,551 log 228 Not Found: /mobiles/15735404103/count/
WARNING 2021-01-04 16:29:39,552 basehttp 154 "GET /mobiles/15735404103/count/ HTTP/1.1" 404 2900
WARNING 2021-01-04 16:29:39,555 log 228 Not Found: /sms_codes/15735404103/
WARNING 2021-01-04 16:29:39,555 basehttp 154 "GET /sms_codes/15735404103/?image_code=&image_code_id=16125a4b-5125-4990-8aeb-1b9ad29fcc03 HTTP/1.1" 404 2955
WARNING 2021-01-04 16:29:39,713 log 228 Not Found: /mobiles/15735404103/count/
WARNING 2021-01-04 16:29:39,717 basehttp 154 "GET /mobiles/15735404103/count/ HTTP/1.1" 404 2900
WARNING 2021-01-04 16:29:39,720 log 228 Not Found: /sms_codes/15735404103/
WARNING 2021-01-04 16:29:39,721 basehttp 154 "GET /sms_codes/15735404103/?image_code=&image_code_id=16125a4b-5125-4990-8aeb-1b9ad29fcc03 HTTP/1.1" 404 2955
WARNING 2021-01-04 16:29:39,941 log 228 Not Found: /sms_codes/15735404103/
WARNING 2021-01-04 16:29:39,943 log 228 Not Found: /mobiles/15735404103/count/
WARNING 2021-01-04 16:29:39,944 basehttp 154 "GET /sms_codes/15735404103/?image_code=&image_code_id=16125a4b-5125-4990-8aeb-1b9ad29fcc03 HTTP/1.1" 404 2955
WARNING 2021-01-04 16:29:39,945 basehttp 154 "GET /mobiles/15735404103/count/ HTTP/1.1" 404 2900
WARNING 2021-01-04 16:29:40,134 log 228 Not Found: /sms_codes/15735404103/
WARNING 2021-01-04 16:29:40,135 log 228 Not Found: /mobiles/15735404103/count/
WARNING 2021-01-04 16:29:40,137 basehttp 154 "GET /sms_codes/15735404103/?image_code=&image_code_id=16125a4b-5125-4990-8aeb-1b9ad29fcc03 HTTP/1.1" 404 2955
WARNING 2021-01-04 16:29:40,137 basehttp 154 "GET /mobiles/15735404103/count/ HTTP/1.1" 404 2900
INFO 2021-01-04 16:30:01,711 basehttp 154 "GET /image_codes/a4ca4fa7-1a79-4e1b-a919-863948abdc16/ HTTP/1.1" 200 3263
INFO 2021-01-04 16:30:07,059 basehttp 154 "GET /usernames/itcast_01/count/ HTTP/1.1" 200 39
WARNING 2021-01-04 16:30:17,036 log 228 Not Found: /mobiles/15735404103/count/
WARNING 2021-01-04 16:30:17,048 basehttp 154 "GET /mobiles/15735404103/count/ HTTP/1.1" 404 2900
WARNING 2021-01-04 16:30:17,140 log 228 Not Found: /mobiles/15735404103/count/
WARNING 2021-01-04 16:30:17,150 log 228 Not Found: /sms_codes/15735404103/
WARNING 2021-01-04 16:30:17,151 basehttp 154 "GET /mobiles/15735404103/count/ HTTP/1.1" 404 2900
WARNING 2021-01-04 16:30:17,152 basehttp 154 "GET /sms_codes/15735404103/?image_code=&image_code_id=a4ca4fa7-1a79-4e1b-a919-863948abdc16 HTTP/1.1" 404 2955
INFO 2021-01-04 16:32:41,216 autoreload 217 /home/ubuntu/Desktop/test/day08/MeiDuo_test/meiduo_mail/apps/verifications/urls.py changed, reloading.
INFO 2021-01-04 16:32:41,971 autoreload 597 Watching for file changes with StatReloader
INFO 2021-01-04 16:32:47,838 basehttp 154 "GET /image_codes/83b1c049-b15e-4c8e-a748-be46d2d53258/ HTTP/1.1" 200 3079
INFO 2021-01-04 16:32:49,371 basehttp 154 "GET /usernames/itcast_01/count/ HTTP/1.1" 200 39
WARNING 2021-01-04 16:32:52,479 log 228 Not Found: /mobiles/15735404103/count/
WARNING 2021-01-04 16:32:52,481 basehttp 154 "GET /mobiles/15735404103/count/ HTTP/1.1" 404 2895
WARNING 2021-01-04 16:32:52,532 log 228 Not Found: /mobiles/15735404103/count/
WARNING 2021-01-04 16:32:52,534 basehttp 154 "GET /mobiles/15735404103/count/ HTTP/1.1" 404 2895
INFO 2021-01-04 16:32:52,550 basehttp 154 "GET /sms_codes/15735404103/?image_code=&image_code_id=83b1c049-b15e-4c8e-a748-be46d2d53258 HTTP/1.1" 200 27
INFO 2021-01-04 16:38:55,683 autoreload 217 /home/ubuntu/Desktop/test/day08/MeiDuo_test/meiduo_mail/apps/verifications/views.py changed, reloading.
INFO 2021-01-04 16:38:56,217 autoreload 597 Watching for file changes with StatReloader
INFO 2021-01-04 16:39:05,096 basehttp 154 "GET /sms_codes/15735404103/?image_code=lugx&image_code_id=83b1c049-b15e-4c8e-a748-be46d2d53258 HTTP/1.1" 200 27
WARNING 2021-01-04 16:39:05,108 log 228 Not Found: /mobiles/15735404103/count/
WARNING 2021-01-04 16:39:05,110 basehttp 154 "GET /mobiles/15735404103/count/ HTTP/1.1" 404 2895
INFO 2021-01-04 16:53:58,051 autoreload 217 /home/ubuntu/Desktop/test/day08/MeiDuo_test/meiduo_mail/apps/verifications/views.py changed, reloading.
INFO 2021-01-04 16:53:58,749 autoreload 597 Watching for file changes with StatReloader
INFO 2021-01-04 16:54:39,839 autoreload 217 /home/ubuntu/Desktop/test/day08/MeiDuo_test/meiduo_mail/apps/verifications/views.py changed, reloading.
INFO 2021-01-04 16:54:40,418 autoreload 597 Watching for file changes with StatReloader
INFO 2021-01-04 16:54:44,039 basehttp 154 "GET /image_codes/45b6c439-a177-4f68-b772-b876e984a7b1/ HTTP/1.1" 200 2886
INFO 2021-01-04 16:54:45,481 basehttp 154 "GET /image_codes/194e0c83-62c3-476c-99ea-62fc2cea1b85/ HTTP/1.1" 200 3212
INFO 2021-01-04 17:14:29,813 autoreload 217 /home/ubuntu/Desktop/test/day08/MeiDuo_test/meiduo_mail/apps/verifications/views.py changed, reloading.
INFO 2021-01-04 17:14:30,697 autoreload 597 Watching for file changes with StatReloader
INFO 2021-01-04 17:47:53,074 autoreload 217 /home/ubuntu/Desktop/test/day08/MeiDuo_test/meiduo_mail/apps/verifications/views.py changed, reloading.
INFO 2021-01-04 17:47:53,713 autoreload 597 Watching for file changes with StatReloader
INFO 2021-01-04 17:54:18,275 autoreload 217 /home/ubuntu/Desktop/test/day08/MeiDuo_test/meiduo_mail/apps/verifications/views.py changed, reloading.
INFO 2021-01-04 17:54:18,959 autoreload 597 Watching for file changes with StatReloader
INFO 2021-01-08 20:27:05,754 autoreload 597 Watching for file changes with StatReloader
WARNING 2021-01-08 20:27:48,677 log 228 Not Found: /carts/simple/
WARNING 2021-01-08 20:27:48,684 basehttp 154 "GET /carts/simple/ HTTP/1.1" 404 3476
INFO 2021-01-08 20:27:49,796 basehttp 154 "OPTIONS /logout/ HTTP/1.1" 200 0
INFO 2021-01-08 20:27:49,804 basehttp 154 "DELETE /logout/ HTTP/1.1" 200 27
WARNING 2021-01-08 20:28:12,592 log 228 Not Found: /oauth_callback/
WARNING 2021-01-08 20:28:12,592 basehttp 154 "GET /oauth_callback/?code=1D569A7C302EB836D276A89B5DE08979 HTTP/1.1" 404 3520
WARNING 2021-01-08 20:32:25,504 log 228 Not Found: /oauth_callback/
WARNING 2021-01-08 20:32:25,513 basehttp 154 "GET /oauth_callback/?code=1D569A7C302EB836D276A89B5DE08979 HTTP/1.1" 404 3520
INFO 2021-01-08 20:37:00,727 autoreload 217 /home/ubuntu/Desktop/test/day08/MeiDuo_test/meiduo_mail/apps/oauth/views.py changed, reloading.
INFO 2021-01-08 20:37:01,356 autoreload 597 Watching for file changes with StatReloader
WARNING 2021-01-08 20:37:04,104 log 228 Not Found: /oauth_callback/
WARNING 2021-01-08 20:37:04,111 basehttp 154 "GET /oauth_callback/?code=1D569A7C302EB836D276A89B5DE08979 HTTP/1.1" 404 3520
WARNING 2021-01-08 20:37:05,591 log 228 Not Found: /oauth_callback/
WARNING 2021-01-08 20:37:05,592 basehttp 154 "GET /oauth_callback/?code=1D569A7C302EB836D276A89B5DE08979 HTTP/1.1" 404 3520
INFO 2021-01-08 20:37:15,066 autoreload 217 /home/ubuntu/Desktop/test/day08/MeiDuo_test/meiduo_mail/apps/oauth/views.py changed, reloading.
INFO 2021-01-08 20:37:15,801 autoreload 597 Watching for file changes with StatReloader
WARNING 2021-01-08 20:37:18,004 log 228 Not Found: /oauth_callback/
WARNING 2021-01-08 20:37:18,005 basehttp 154 "GET /oauth_callback/?code=1D569A7C302EB836D276A89B5DE08979 HTTP/1.1" 404 3520
WARNING 2021-01-08 20:37:31,620 log 228 Not Found: /oauth_callback.html
WARNING 2021-01-08 20:37:31,622 basehttp 154 "GET /oauth_callback.html?code=1D569A7C302EB836D276A89B5DE08979 HTTP/1.1" 404 3532
WARNING 2021-01-08 20:37:31,730 log 228 Not Found: /favicon.ico
WARNING 2021-01-08 20:37:31,732 basehttp 154 "GET /favicon.ico HTTP/1.1" 404 3470
INFO 2021-01-08 20:37:49,785 autoreload 217 /home/ubuntu/Desktop/test/day08/MeiDuo_test/meiduo_mail/apps/oauth/urls.py changed, reloading.
INFO 2021-01-08 20:37:50,636 autoreload 597 Watching for file changes with StatReloader
ERROR 2021-01-08 20:37:54,687 log 228 Internal Server Error: /oauth_callback/
Traceback (most recent call last):
  File "/home/ubuntu/.virtualenvs/py3_shunyi_44/lib/python3.6/site-packages/django/db/backends/utils.py", line 84, in _execute
    return self.cursor.execute(sql, params)
  File "/home/ubuntu/.virtualenvs/py3_shunyi_44/lib/python3.6/site-packages/django/db/backends/mysql/base.py", line 71, in execute
    return self.cursor.execute(query, args)
  File "/home/ubuntu/.virtualenvs/py3_shunyi_44/lib/python3.6/site-packages/MySQLdb/cursors.py", line 206, in execute
    res = self._query(query)
  File "/home/ubuntu/.virtualenvs/py3_shunyi_44/lib/python3.6/site-packages/MySQLdb/cursors.py", line 319, in _query
    db.query(q)
  File "/home/ubuntu/.virtualenvs/py3_shunyi_44/lib/python3.6/site-packages/MySQLdb/connections.py", line 259, in query
    _mysql.connection.query(self, query)
MySQLdb._exceptions.ProgrammingError: (1146, "Table 'meiduo_mail_test.tb_oauth_qq' doesn't exist")

The above exception was the direct cause of the following exception:

Traceback (most recent call last):
  File "/home/ubuntu/.virtualenvs/py3_shunyi_44/lib/python3.6/site-packages/django/core/handlers/exception.py", line 34, in inner
    response = get_response(request)
  File "/home/ubuntu/.virtualenvs/py3_shunyi_44/lib/python3.6/site-packages/django/core/handlers/base.py", line 115, in _get_response
    response = self.process_exception_by_middleware(e, request)
  File "/home/ubuntu/.virtualenvs/py3_shunyi_44/lib/python3.6/site-packages/django/core/handlers/base.py", line 113, in _get_response
    response = wrapped_callback(request, *callback_args, **callback_kwargs)
  File "/home/ubuntu/.virtualenvs/py3_shunyi_44/lib/python3.6/site-packages/django/views/generic/base.py", line 71, in view
    return self.dispatch(request, *args, **kwargs)
  File "/home/ubuntu/.virtualenvs/py3_shunyi_44/lib/python3.6/site-packages/django/views/generic/base.py", line 97, in dispatch
    return handler(request, *args, **kwargs)
  File "/home/ubuntu/Desktop/test/day08/MeiDuo_test/meiduo_mail/apps/oauth/views.py", line 31, in get
    qquser = OAuthQQUser.objects.get(openid=openid)
  File "/home/ubuntu/.virtualenvs/py3_shunyi_44/lib/python3.6/site-packages/django/db/models/manager.py", line 82, in manager_method
    return getattr(self.get_queryset(), name)(*args, **kwargs)
  File "/home/ubuntu/.virtualenvs/py3_shunyi_44/lib/python3.6/site-packages/django/db/models/query.py", line 402, in get
    num = len(clone)
  File "/home/ubuntu/.virtualenvs/py3_shunyi_44/lib/python3.6/site-packages/django/db/models/query.py", line 256, in __len__
    self._fetch_all()
  File "/home/ubuntu/.virtualenvs/py3_shunyi_44/lib/python3.6/site-packages/django/db/models/query.py", line 1242, in _fetch_all
    self._result_cache = list(self._iterable_class(self))
  File "/home/ubuntu/.virtualenvs/py3_shunyi_44/lib/python3.6/site-packages/django/db/models/query.py", line 55, in __iter__
    results = compiler.execute_sql(chunked_fetch=self.chunked_fetch, chunk_size=self.chunk_size)
  File "/home/ubuntu/.virtualenvs/py3_shunyi_44/lib/python3.6/site-packages/django/db/models/sql/compiler.py", line 1100, in execute_sql
    cursor.execute(sql, params)
  File "/home/ubuntu/.virtualenvs/py3_shunyi_44/lib/python3.6/site-packages/django/db/backends/utils.py", line 99, in execute
    return super().execute(sql, params)
  File "/home/ubuntu/.virtualenvs/py3_shunyi_44/lib/python3.6/site-packages/django/db/backends/utils.py", line 67, in execute
    return self._execute_with_wrappers(sql, params, many=False, executor=self._execute)
  File "/home/ubuntu/.virtualenvs/py3_shunyi_44/lib/python3.6/site-packages/django/db/backends/utils.py", line 76, in _execute_with_wrappers
    return executor(sql, params, many, context)
  File "/home/ubuntu/.virtualenvs/py3_shunyi_44/lib/python3.6/site-packages/django/db/backends/utils.py", line 84, in _execute
    return self.cursor.execute(sql, params)
  File "/home/ubuntu/.virtualenvs/py3_shunyi_44/lib/python3.6/site-packages/django/db/utils.py", line 89, in __exit__
    raise dj_exc_value.with_traceback(traceback) from exc_value
  File "/home/ubuntu/.virtualenvs/py3_shunyi_44/lib/python3.6/site-packages/django/db/backends/utils.py", line 84, in _execute
    return self.cursor.execute(sql, params)
  File "/home/ubuntu/.virtualenvs/py3_shunyi_44/lib/python3.6/site-packages/django/db/backends/mysql/base.py", line 71, in execute
    return self.cursor.execute(query, args)
  File "/home/ubuntu/.virtualenvs/py3_shunyi_44/lib/python3.6/site-packages/MySQLdb/cursors.py", line 206, in execute
    res = self._query(query)
  File "/home/ubuntu/.virtualenvs/py3_shunyi_44/lib/python3.6/site-packages/MySQLdb/cursors.py", line 319, in _query
    db.query(q)
  File "/home/ubuntu/.virtualenvs/py3_shunyi_44/lib/python3.6/site-packages/MySQLdb/connections.py", line 259, in query
    _mysql.connection.query(self, query)
django.db.utils.ProgrammingError: (1146, "Table 'meiduo_mail_test.tb_oauth_qq' doesn't exist")
ERROR 2021-01-08 20:37:54,699 basehttp 154 "GET /oauth_callback/?code=1D569A7C302EB836D276A89B5DE08979 HTTP/1.1" 500 179304
ERROR 2021-01-08 20:37:54,906 log 228 Internal Server Error: /oauth_callback/
Traceback (most recent call last):
  File "/home/ubuntu/.virtualenvs/py3_shunyi_44/lib/python3.6/site-packages/django/core/handlers/exception.py", line 34, in inner
    response = get_response(request)
  File "/home/ubuntu/.virtualenvs/py3_shunyi_44/lib/python3.6/site-packages/django/core/handlers/base.py", line 115, in _get_response
    response = self.process_exception_by_middleware(e, request)
  File "/home/ubuntu/.virtualenvs/py3_shunyi_44/lib/python3.6/site-packages/django/core/handlers/base.py", line 113, in _get_response
    response = wrapped_callback(request, *callback_args, **callback_kwargs)
  File "/home/ubuntu/.virtualenvs/py3_shunyi_44/lib/python3.6/site-packages/django/views/generic/base.py", line 71, in view
    return self.dispatch(request, *args, **kwargs)
  File "/home/ubuntu/.virtualenvs/py3_shunyi_44/lib/python3.6/site-packages/django/views/generic/base.py", line 97, in dispatch
    return handler(request, *args, **kwargs)
  File "/home/ubuntu/Desktop/test/day08/MeiDuo_test/meiduo_mail/apps/oauth/views.py", line 24, in get
    access_token = qq.get_access_token(code)
  File "/home/ubuntu/.virtualenvs/py3_shunyi_44/lib/python3.6/site-packages/QQLoginTool/QQtool.py", line 63, in get_access_token
    raise Exception('access_token获取失败')
Exception: access_token获取失败
ERROR 2021-01-08 20:37:54,909 basehttp 154 "GET /oauth_callback/?code=1D569A7C302EB836D276A89B5DE08979 HTTP/1.1" 500 88832
ERROR 2021-01-08 20:37:55,458 log 228 Internal Server Error: /oauth_callback/
Traceback (most recent call last):
  File "/home/ubuntu/.virtualenvs/py3_shunyi_44/lib/python3.6/site-packages/django/core/handlers/exception.py", line 34, in inner
    response = get_response(request)
  File "/home/ubuntu/.virtualenvs/py3_shunyi_44/lib/python3.6/site-packages/django/core/handlers/base.py", line 115, in _get_response
    response = self.process_exception_by_middleware(e, request)
  File "/home/ubuntu/.virtualenvs/py3_shunyi_44/lib/python3.6/site-packages/django/core/handlers/base.py", line 113, in _get_response
    response = wrapped_callback(request, *callback_args, **callback_kwargs)
  File "/home/ubuntu/.virtualenvs/py3_shunyi_44/lib/python3.6/site-packages/django/views/generic/base.py", line 71, in view
    return self.dispatch(request, *args, **kwargs)
  File "/home/ubuntu/.virtualenvs/py3_shunyi_44/lib/python3.6/site-packages/django/views/generic/base.py", line 97, in dispatch
    return handler(request, *args, **kwargs)
  File "/home/ubuntu/Desktop/test/day08/MeiDuo_test/meiduo_mail/apps/oauth/views.py", line 24, in get
    access_token = qq.get_access_token(code)
  File "/home/ubuntu/.virtualenvs/py3_shunyi_44/lib/python3.6/site-packages/QQLoginTool/QQtool.py", line 63, in get_access_token
    raise Exception('access_token获取失败')
Exception: access_token获取失败
ERROR 2021-01-08 20:37:55,459 basehttp 154 "GET /oauth_callback/?code=1D569A7C302EB836D276A89B5DE08979 HTTP/1.1" 500 88832
ERROR 2021-01-08 20:37:56,763 log 228 Internal Server Error: /oauth_callback/
Traceback (most recent call last):
  File "/home/ubuntu/.virtualenvs/py3_shunyi_44/lib/python3.6/site-packages/django/core/handlers/exception.py", line 34, in inner
    response = get_response(request)
  File "/home/ubuntu/.virtualenvs/py3_shunyi_44/lib/python3.6/site-packages/django/core/handlers/base.py", line 115, in _get_response
    response = self.process_exception_by_middleware(e, request)
  File "/home/ubuntu/.virtualenvs/py3_shunyi_44/lib/python3.6/site-packages/django/core/handlers/base.py", line 113, in _get_response
    response = wrapped_callback(request, *callback_args, **callback_kwargs)
  File "/home/ubuntu/.virtualenvs/py3_shunyi_44/lib/python3.6/site-packages/django/views/generic/base.py", line 71, in view
    return self.dispatch(request, *args, **kwargs)
  File "/home/ubuntu/.virtualenvs/py3_shunyi_44/lib/python3.6/site-packages/django/views/generic/base.py", line 97, in dispatch
    return handler(request, *args, **kwargs)
  File "/home/ubuntu/Desktop/test/day08/MeiDuo_test/meiduo_mail/apps/oauth/views.py", line 24, in get
    access_token = qq.get_access_token(code)
  File "/home/ubuntu/.virtualenvs/py3_shunyi_44/lib/python3.6/site-packages/QQLoginTool/QQtool.py", line 63, in get_access_token
    raise Exception('access_token获取失败')
Exception: access_token获取失败
ERROR 2021-01-08 20:37:56,765 basehttp 154 "GET /oauth_callback/?code=1D569A7C302EB836D276A89B5DE08979 HTTP/1.1" 500 88832
ERROR 2021-01-08 20:37:57,589 log 228 Internal Server Error: /oauth_callback/
Traceback (most recent call last):
  File "/home/ubuntu/.virtualenvs/py3_shunyi_44/lib/python3.6/site-packages/django/core/handlers/exception.py", line 34, in inner
    response = get_response(request)
  File "/home/ubuntu/.virtualenvs/py3_shunyi_44/lib/python3.6/site-packages/django/core/handlers/base.py", line 115, in _get_response
    response = self.process_exception_by_middleware(e, request)
  File "/home/ubuntu/.virtualenvs/py3_shunyi_44/lib/python3.6/site-packages/django/core/handlers/base.py", line 113, in _get_response
    response = wrapped_callback(request, *callback_args, **callback_kwargs)
  File "/home/ubuntu/.virtualenvs/py3_shunyi_44/lib/python3.6/site-packages/django/views/generic/base.py", line 71, in view
    return self.dispatch(request, *args, **kwargs)
  File "/home/ubuntu/.virtualenvs/py3_shunyi_44/lib/python3.6/site-packages/django/views/generic/base.py", line 97, in dispatch
    return handler(request, *args, **kwargs)
  File "/home/ubuntu/Desktop/test/day08/MeiDuo_test/meiduo_mail/apps/oauth/views.py", line 24, in get
    access_token = qq.get_access_token(code)
  File "/home/ubuntu/.virtualenvs/py3_shunyi_44/lib/python3.6/site-packages/QQLoginTool/QQtool.py", line 63, in get_access_token
    raise Exception('access_token获取失败')
Exception: access_token获取失败
ERROR 2021-01-08 20:37:57,591 basehttp 154 "GET /oauth_callback/?code=1D569A7C302EB836D276A89B5DE08979 HTTP/1.1" 500 88832
WARNING 2021-01-08 20:38:01,441 log 228 Not Found: /oauth_callback.html
WARNING 2021-01-08 20:38:01,443 basehttp 154 "GET /oauth_callback.html?code=1D569A7C302EB836D276A89B5DE08979 HTTP/1.1" 404 3533
ERROR 2021-01-08 20:38:41,803 log 228 Internal Server Error: /oauth_callback/
Traceback (most recent call last):
  File "/home/ubuntu/.virtualenvs/py3_shunyi_44/lib/python3.6/site-packages/django/core/handlers/exception.py", line 34, in inner
    response = get_response(request)
  File "/home/ubuntu/.virtualenvs/py3_shunyi_44/lib/python3.6/site-packages/django/core/handlers/base.py", line 115, in _get_response
    response = self.process_exception_by_middleware(e, request)
  File "/home/ubuntu/.virtualenvs/py3_shunyi_44/lib/python3.6/site-packages/django/core/handlers/base.py", line 113, in _get_response
    response = wrapped_callback(request, *callback_args, **callback_kwargs)
  File "/home/ubuntu/.virtualenvs/py3_shunyi_44/lib/python3.6/site-packages/django/views/generic/base.py", line 71, in view
    return self.dispatch(request, *args, **kwargs)
  File "/home/ubuntu/.virtualenvs/py3_shunyi_44/lib/python3.6/site-packages/django/views/generic/base.py", line 97, in dispatch
    return handler(request, *args, **kwargs)
  File "/home/ubuntu/Desktop/test/day08/MeiDuo_test/meiduo_mail/apps/oauth/views.py", line 24, in get
    access_token = qq.get_access_token(code)
  File "/home/ubuntu/.virtualenvs/py3_shunyi_44/lib/python3.6/site-packages/QQLoginTool/QQtool.py", line 63, in get_access_token
    raise Exception('access_token获取失败')
Exception: access_token获取失败
ERROR 2021-01-08 20:38:41,805 basehttp 154 "GET /oauth_callback/?code=1D569A7C302EB836D276A89B5DE08979 HTTP/1.1" 500 88832
INFO 2021-01-08 20:39:22,487 autoreload 217 /home/ubuntu/Desktop/test/day08/MeiDuo_test/meiduo_mail/apps/oauth/views.py changed, reloading.
INFO 2021-01-08 20:39:23,056 autoreload 597 Watching for file changes with StatReloader
WARNING 2021-01-08 20:39:35,981 log 228 Not Found: /carts/simple/
WARNING 2021-01-08 20:39:35,984 basehttp 154 "GET /carts/simple/ HTTP/1.1" 404 3477
ERROR 2021-01-08 20:39:57,674 log 228 Internal Server Error: /oauth_callback/
Traceback (most recent call last):
  File "/home/ubuntu/.virtualenvs/py3_shunyi_44/lib/python3.6/site-packages/django/db/backends/utils.py", line 84, in _execute
    return self.cursor.execute(sql, params)
  File "/home/ubuntu/.virtualenvs/py3_shunyi_44/lib/python3.6/site-packages/django/db/backends/mysql/base.py", line 71, in execute
    return self.cursor.execute(query, args)
  File "/home/ubuntu/.virtualenvs/py3_shunyi_44/lib/python3.6/site-packages/MySQLdb/cursors.py", line 206, in execute
    res = self._query(query)
  File "/home/ubuntu/.virtualenvs/py3_shunyi_44/lib/python3.6/site-packages/MySQLdb/cursors.py", line 319, in _query
    db.query(q)
  File "/home/ubuntu/.virtualenvs/py3_shunyi_44/lib/python3.6/site-packages/MySQLdb/connections.py", line 259, in query
    _mysql.connection.query(self, query)
MySQLdb._exceptions.ProgrammingError: (1146, "Table 'meiduo_mail_test.tb_oauth_qq' doesn't exist")

The above exception was the direct cause of the following exception:

Traceback (most recent call last):
  File "/home/ubuntu/.virtualenvs/py3_shunyi_44/lib/python3.6/site-packages/django/core/handlers/exception.py", line 34, in inner
    response = get_response(request)
  File "/home/ubuntu/.virtualenvs/py3_shunyi_44/lib/python3.6/site-packages/django/core/handlers/base.py", line 115, in _get_response
    response = self.process_exception_by_middleware(e, request)
  File "/home/ubuntu/.virtualenvs/py3_shunyi_44/lib/python3.6/site-packages/django/core/handlers/base.py", line 113, in _get_response
    response = wrapped_callback(request, *callback_args, **callback_kwargs)
  File "/home/ubuntu/.virtualenvs/py3_shunyi_44/lib/python3.6/site-packages/django/views/generic/base.py", line 71, in view
    return self.dispatch(request, *args, **kwargs)
  File "/home/ubuntu/.virtualenvs/py3_shunyi_44/lib/python3.6/site-packages/django/views/generic/base.py", line 97, in dispatch
    return handler(request, *args, **kwargs)
  File "/home/ubuntu/Desktop/test/day08/MeiDuo_test/meiduo_mail/apps/oauth/views.py", line 31, in get
    qquser = OAuthQQUser.objects.get(openid=openid)
  File "/home/ubuntu/.virtualenvs/py3_shunyi_44/lib/python3.6/site-packages/django/db/models/manager.py", line 82, in manager_method
    return getattr(self.get_queryset(), name)(*args, **kwargs)
  File "/home/ubuntu/.virtualenvs/py3_shunyi_44/lib/python3.6/site-packages/django/db/models/query.py", line 402, in get
    num = len(clone)
  File "/home/ubuntu/.virtualenvs/py3_shunyi_44/lib/python3.6/site-packages/django/db/models/query.py", line 256, in __len__
    self._fetch_all()
  File "/home/ubuntu/.virtualenvs/py3_shunyi_44/lib/python3.6/site-packages/django/db/models/query.py", line 1242, in _fetch_all
    self._result_cache = list(self._iterable_class(self))
  File "/home/ubuntu/.virtualenvs/py3_shunyi_44/lib/python3.6/site-packages/django/db/models/query.py", line 55, in __iter__
    results = compiler.execute_sql(chunked_fetch=self.chunked_fetch, chunk_size=self.chunk_size)
  File "/home/ubuntu/.virtualenvs/py3_shunyi_44/lib/python3.6/site-packages/django/db/models/sql/compiler.py", line 1100, in execute_sql
    cursor.execute(sql, params)
  File "/home/ubuntu/.virtualenvs/py3_shunyi_44/lib/python3.6/site-packages/django/db/backends/utils.py", line 99, in execute
    return super().execute(sql, params)
  File "/home/ubuntu/.virtualenvs/py3_shunyi_44/lib/python3.6/site-packages/django/db/backends/utils.py", line 67, in execute
    return self._execute_with_wrappers(sql, params, many=False, executor=self._execute)
  File "/home/ubuntu/.virtualenvs/py3_shunyi_44/lib/python3.6/site-packages/django/db/backends/utils.py", line 76, in _execute_with_wrappers
    return executor(sql, params, many, context)
  File "/home/ubuntu/.virtualenvs/py3_shunyi_44/lib/python3.6/site-packages/django/db/backends/utils.py", line 84, in _execute
    return self.cursor.execute(sql, params)
  File "/home/ubuntu/.virtualenvs/py3_shunyi_44/lib/python3.6/site-packages/django/db/utils.py", line 89, in __exit__
    raise dj_exc_value.with_traceback(traceback) from exc_value
  File "/home/ubuntu/.virtualenvs/py3_shunyi_44/lib/python3.6/site-packages/django/db/backends/utils.py", line 84, in _execute
    return self.cursor.execute(sql, params)
  File "/home/ubuntu/.virtualenvs/py3_shunyi_44/lib/python3.6/site-packages/django/db/backends/mysql/base.py", line 71, in execute
    return self.cursor.execute(query, args)
  File "/home/ubuntu/.virtualenvs/py3_shunyi_44/lib/python3.6/site-packages/MySQLdb/cursors.py", line 206, in execute
    res = self._query(query)
  File "/home/ubuntu/.virtualenvs/py3_shunyi_44/lib/python3.6/site-packages/MySQLdb/cursors.py", line 319, in _query
    db.query(q)
  File "/home/ubuntu/.virtualenvs/py3_shunyi_44/lib/python3.6/site-packages/MySQLdb/connections.py", line 259, in query
    _mysql.connection.query(self, query)
django.db.utils.ProgrammingError: (1146, "Table 'meiduo_mail_test.tb_oauth_qq' doesn't exist")
ERROR 2021-01-08 20:39:57,689 basehttp 154 "GET /oauth_callback/?code=1E164AC849CC76F9EAA9D65DE24DD288 HTTP/1.1" 500 179304
INFO 2021-01-08 20:40:28,297 autoreload 217 /home/ubuntu/Desktop/test/day08/MeiDuo_test/meiduo_mail/apps/oauth/views.py changed, reloading.
INFO 2021-01-08 20:40:29,133 autoreload 597 Watching for file changes with StatReloader
ERROR 2021-01-08 20:40:32,065 log 228 Internal Server Error: /oauth_callback/
Traceback (most recent call last):
  File "/home/ubuntu/.virtualenvs/py3_shunyi_44/lib/python3.6/site-packages/django/core/handlers/exception.py", line 34, in inner
    response = get_response(request)
  File "/home/ubuntu/.virtualenvs/py3_shunyi_44/lib/python3.6/site-packages/django/core/handlers/base.py", line 115, in _get_response
    response = self.process_exception_by_middleware(e, request)
  File "/home/ubuntu/.virtualenvs/py3_shunyi_44/lib/python3.6/site-packages/django/core/handlers/base.py", line 113, in _get_response
    response = wrapped_callback(request, *callback_args, **callback_kwargs)
  File "/home/ubuntu/.virtualenvs/py3_shunyi_44/lib/python3.6/site-packages/django/views/generic/base.py", line 71, in view
    return self.dispatch(request, *args, **kwargs)
  File "/home/ubuntu/.virtualenvs/py3_shunyi_44/lib/python3.6/site-packages/django/views/generic/base.py", line 97, in dispatch
    return handler(request, *args, **kwargs)
  File "/home/ubuntu/Desktop/test/day08/MeiDuo_test/meiduo_mail/apps/oauth/views.py", line 24, in get
    access_token = qq.get_access_token(code)
  File "/home/ubuntu/.virtualenvs/py3_shunyi_44/lib/python3.6/site-packages/QQLoginTool/QQtool.py", line 63, in get_access_token
    raise Exception('access_token获取失败')
Exception: access_token获取失败
ERROR 2021-01-08 20:40:32,067 basehttp 154 "GET /oauth_callback/?code=1E164AC849CC76F9EAA9D65DE24DD288 HTTP/1.1" 500 88832
ERROR 2021-01-08 20:40:40,310 log 228 Internal Server Error: /oauth_callback/
Traceback (most recent call last):
  File "/home/ubuntu/.virtualenvs/py3_shunyi_44/lib/python3.6/site-packages/django/db/backends/utils.py", line 84, in _execute
    return self.cursor.execute(sql, params)
  File "/home/ubuntu/.virtualenvs/py3_shunyi_44/lib/python3.6/site-packages/django/db/backends/mysql/base.py", line 71, in execute
    return self.cursor.execute(query, args)
  File "/home/ubuntu/.virtualenvs/py3_shunyi_44/lib/python3.6/site-packages/MySQLdb/cursors.py", line 206, in execute
    res = self._query(query)
  File "/home/ubuntu/.virtualenvs/py3_shunyi_44/lib/python3.6/site-packages/MySQLdb/cursors.py", line 319, in _query
    db.query(q)
  File "/home/ubuntu/.virtualenvs/py3_shunyi_44/lib/python3.6/site-packages/MySQLdb/connections.py", line 259, in query
    _mysql.connection.query(self, query)
MySQLdb._exceptions.ProgrammingError: (1146, "Table 'meiduo_mail_test.tb_oauth_qq' doesn't exist")

The above exception was the direct cause of the following exception:

Traceback (most recent call last):
  File "/home/ubuntu/.virtualenvs/py3_shunyi_44/lib/python3.6/site-packages/django/core/handlers/exception.py", line 34, in inner
    response = get_response(request)
  File "/home/ubuntu/.virtualenvs/py3_shunyi_44/lib/python3.6/site-packages/django/core/handlers/base.py", line 115, in _get_response
    response = self.process_exception_by_middleware(e, request)
  File "/home/ubuntu/.virtualenvs/py3_shunyi_44/lib/python3.6/site-packages/django/core/handlers/base.py", line 113, in _get_response
    response = wrapped_callback(request, *callback_args, **callback_kwargs)
  File "/home/ubuntu/.virtualenvs/py3_shunyi_44/lib/python3.6/site-packages/django/views/generic/base.py", line 71, in view
    return self.dispatch(request, *args, **kwargs)
  File "/home/ubuntu/.virtualenvs/py3_shunyi_44/lib/python3.6/site-packages/django/views/generic/base.py", line 97, in dispatch
    return handler(request, *args, **kwargs)
  File "/home/ubuntu/Desktop/test/day08/MeiDuo_test/meiduo_mail/apps/oauth/views.py", line 31, in get
    qquser = OAuthQQUser.objects.get(openid=openid)
  File "/home/ubuntu/.virtualenvs/py3_shunyi_44/lib/python3.6/site-packages/django/db/models/manager.py", line 82, in manager_method
    return getattr(self.get_queryset(), name)(*args, **kwargs)
  File "/home/ubuntu/.virtualenvs/py3_shunyi_44/lib/python3.6/site-packages/django/db/models/query.py", line 402, in get
    num = len(clone)
  File "/home/ubuntu/.virtualenvs/py3_shunyi_44/lib/python3.6/site-packages/django/db/models/query.py", line 256, in __len__
    self._fetch_all()
  File "/home/ubuntu/.virtualenvs/py3_shunyi_44/lib/python3.6/site-packages/django/db/models/query.py", line 1242, in _fetch_all
    self._result_cache = list(self._iterable_class(self))
  File "/home/ubuntu/.virtualenvs/py3_shunyi_44/lib/python3.6/site-packages/django/db/models/query.py", line 55, in __iter__
    results = compiler.execute_sql(chunked_fetch=self.chunked_fetch, chunk_size=self.chunk_size)
  File "/home/ubuntu/.virtualenvs/py3_shunyi_44/lib/python3.6/site-packages/django/db/models/sql/compiler.py", line 1100, in execute_sql
    cursor.execute(sql, params)
  File "/home/ubuntu/.virtualenvs/py3_shunyi_44/lib/python3.6/site-packages/django/db/backends/utils.py", line 99, in execute
    return super().execute(sql, params)
  File "/home/ubuntu/.virtualenvs/py3_shunyi_44/lib/python3.6/site-packages/django/db/backends/utils.py", line 67, in execute
    return self._execute_with_wrappers(sql, params, many=False, executor=self._execute)
  File "/home/ubuntu/.virtualenvs/py3_shunyi_44/lib/python3.6/site-packages/django/db/backends/utils.py", line 76, in _execute_with_wrappers
    return executor(sql, params, many, context)
  File "/home/ubuntu/.virtualenvs/py3_shunyi_44/lib/python3.6/site-packages/django/db/backends/utils.py", line 84, in _execute
    return self.cursor.execute(sql, params)
  File "/home/ubuntu/.virtualenvs/py3_shunyi_44/lib/python3.6/site-packages/django/db/utils.py", line 89, in __exit__
    raise dj_exc_value.with_traceback(traceback) from exc_value
  File "/home/ubuntu/.virtualenvs/py3_shunyi_44/lib/python3.6/site-packages/django/db/backends/utils.py", line 84, in _execute
    return self.cursor.execute(sql, params)
  File "/home/ubuntu/.virtualenvs/py3_shunyi_44/lib/python3.6/site-packages/django/db/backends/mysql/base.py", line 71, in execute
    return self.cursor.execute(query, args)
  File "/home/ubuntu/.virtualenvs/py3_shunyi_44/lib/python3.6/site-packages/MySQLdb/cursors.py", line 206, in execute
    res = self._query(query)
  File "/home/ubuntu/.virtualenvs/py3_shunyi_44/lib/python3.6/site-packages/MySQLdb/cursors.py", line 319, in _query
    db.query(q)
  File "/home/ubuntu/.virtualenvs/py3_shunyi_44/lib/python3.6/site-packages/MySQLdb/connections.py", line 259, in query
    _mysql.connection.query(self, query)
django.db.utils.ProgrammingError: (1146, "Table 'meiduo_mail_test.tb_oauth_qq' doesn't exist")
ERROR 2021-01-08 20:40:40,313 basehttp 154 "GET /oauth_callback/?code=50D7FC97DEEED3B234881845AEB33449 HTTP/1.1" 500 179300
INFO 2021-01-08 20:41:09,696 basehttp 154 "GET /oauth_callback/ HTTP/1.1" 200 55
ERROR 2021-01-08 20:41:25,300 log 228 Internal Server Error: /oauth_callback/
Traceback (most recent call last):
  File "/home/ubuntu/.virtualenvs/py3_shunyi_44/lib/python3.6/site-packages/django/core/handlers/exception.py", line 34, in inner
    response = get_response(request)
  File "/home/ubuntu/.virtualenvs/py3_shunyi_44/lib/python3.6/site-packages/django/core/handlers/base.py", line 115, in _get_response
    response = self.process_exception_by_middleware(e, request)
  File "/home/ubuntu/.virtualenvs/py3_shunyi_44/lib/python3.6/site-packages/django/core/handlers/base.py", line 113, in _get_response
    response = wrapped_callback(request, *callback_args, **callback_kwargs)
  File "/home/ubuntu/.virtualenvs/py3_shunyi_44/lib/python3.6/site-packages/django/views/generic/base.py", line 71, in view
    return self.dispatch(request, *args, **kwargs)
  File "/home/ubuntu/.virtualenvs/py3_shunyi_44/lib/python3.6/site-packages/django/views/generic/base.py", line 97, in dispatch
    return handler(request, *args, **kwargs)
  File "/home/ubuntu/Desktop/test/day08/MeiDuo_test/meiduo_mail/apps/oauth/views.py", line 24, in get
    access_token = qq.get_access_token(code)
  File "/home/ubuntu/.virtualenvs/py3_shunyi_44/lib/python3.6/site-packages/QQLoginTool/QQtool.py", line 63, in get_access_token
    raise Exception('access_token获取失败')
Exception: access_token获取失败
ERROR 2021-01-08 20:41:25,301 basehttp 154 "GET /oauth_callback/?code=50D7FC97DEEED3B234881845AEB33449 HTTP/1.1" 500 88705
INFO 2021-01-08 20:43:14,042 autoreload 597 Watching for file changes with StatReloader
ERROR 2021-01-08 20:43:25,202 log 228 Internal Server Error: /oauth_callback/
Traceback (most recent call last):
  File "/home/ubuntu/.virtualenvs/py3_shunyi_44/lib/python3.6/site-packages/django/db/backends/utils.py", line 84, in _execute
    return self.cursor.execute(sql, params)
  File "/home/ubuntu/.virtualenvs/py3_shunyi_44/lib/python3.6/site-packages/django/db/backends/mysql/base.py", line 71, in execute
    return self.cursor.execute(query, args)
  File "/home/ubuntu/.virtualenvs/py3_shunyi_44/lib/python3.6/site-packages/MySQLdb/cursors.py", line 206, in execute
    res = self._query(query)
  File "/home/ubuntu/.virtualenvs/py3_shunyi_44/lib/python3.6/site-packages/MySQLdb/cursors.py", line 319, in _query
    db.query(q)
  File "/home/ubuntu/.virtualenvs/py3_shunyi_44/lib/python3.6/site-packages/MySQLdb/connections.py", line 259, in query
    _mysql.connection.query(self, query)
MySQLdb._exceptions.ProgrammingError: (1146, "Table 'meiduo_mail_test.tb_oauth_qq' doesn't exist")

The above exception was the direct cause of the following exception:

Traceback (most recent call last):
  File "/home/ubuntu/.virtualenvs/py3_shunyi_44/lib/python3.6/site-packages/django/core/handlers/exception.py", line 34, in inner
    response = get_response(request)
  File "/home/ubuntu/.virtualenvs/py3_shunyi_44/lib/python3.6/site-packages/django/core/handlers/base.py", line 115, in _get_response
    response = self.process_exception_by_middleware(e, request)
  File "/home/ubuntu/.virtualenvs/py3_shunyi_44/lib/python3.6/site-packages/django/core/handlers/base.py", line 113, in _get_response
    response = wrapped_callback(request, *callback_args, **callback_kwargs)
  File "/home/ubuntu/.virtualenvs/py3_shunyi_44/lib/python3.6/site-packages/django/views/generic/base.py", line 71, in view
    return self.dispatch(request, *args, **kwargs)
  File "/home/ubuntu/.virtualenvs/py3_shunyi_44/lib/python3.6/site-packages/django/views/generic/base.py", line 97, in dispatch
    return handler(request, *args, **kwargs)
  File "/home/ubuntu/Desktop/test/day08/MeiDuo_test/meiduo_mail/apps/oauth/views.py", line 31, in get
    qquser = OAuthQQUser.objects.get(openid=openid)
  File "/home/ubuntu/.virtualenvs/py3_shunyi_44/lib/python3.6/site-packages/django/db/models/manager.py", line 82, in manager_method
    return getattr(self.get_queryset(), name)(*args, **kwargs)
  File "/home/ubuntu/.virtualenvs/py3_shunyi_44/lib/python3.6/site-packages/django/db/models/query.py", line 402, in get
    num = len(clone)
  File "/home/ubuntu/.virtualenvs/py3_shunyi_44/lib/python3.6/site-packages/django/db/models/query.py", line 256, in __len__
    self._fetch_all()
  File "/home/ubuntu/.virtualenvs/py3_shunyi_44/lib/python3.6/site-packages/django/db/models/query.py", line 1242, in _fetch_all
    self._result_cache = list(self._iterable_class(self))
  File "/home/ubuntu/.virtualenvs/py3_shunyi_44/lib/python3.6/site-packages/django/db/models/query.py", line 55, in __iter__
    results = compiler.execute_sql(chunked_fetch=self.chunked_fetch, chunk_size=self.chunk_size)
  File "/home/ubuntu/.virtualenvs/py3_shunyi_44/lib/python3.6/site-packages/django/db/models/sql/compiler.py", line 1100, in execute_sql
    cursor.execute(sql, params)
  File "/home/ubuntu/.virtualenvs/py3_shunyi_44/lib/python3.6/site-packages/django/db/backends/utils.py", line 99, in execute
    return super().execute(sql, params)
  File "/home/ubuntu/.virtualenvs/py3_shunyi_44/lib/python3.6/site-packages/django/db/backends/utils.py", line 67, in execute
    return self._execute_with_wrappers(sql, params, many=False, executor=self._execute)
  File "/home/ubuntu/.virtualenvs/py3_shunyi_44/lib/python3.6/site-packages/django/db/backends/utils.py", line 76, in _execute_with_wrappers
    return executor(sql, params, many, context)
  File "/home/ubuntu/.virtualenvs/py3_shunyi_44/lib/python3.6/site-packages/django/db/backends/utils.py", line 84, in _execute
    return self.cursor.execute(sql, params)
  File "/home/ubuntu/.virtualenvs/py3_shunyi_44/lib/python3.6/site-packages/django/db/utils.py", line 89, in __exit__
    raise dj_exc_value.with_traceback(traceback) from exc_value
  File "/home/ubuntu/.virtualenvs/py3_shunyi_44/lib/python3.6/site-packages/django/db/backends/utils.py", line 84, in _execute
    return self.cursor.execute(sql, params)
  File "/home/ubuntu/.virtualenvs/py3_shunyi_44/lib/python3.6/site-packages/django/db/backends/mysql/base.py", line 71, in execute
    return self.cursor.execute(query, args)
  File "/home/ubuntu/.virtualenvs/py3_shunyi_44/lib/python3.6/site-packages/MySQLdb/cursors.py", line 206, in execute
    res = self._query(query)
  File "/home/ubuntu/.virtualenvs/py3_shunyi_44/lib/python3.6/site-packages/MySQLdb/cursors.py", line 319, in _query
    db.query(q)
  File "/home/ubuntu/.virtualenvs/py3_shunyi_44/lib/python3.6/site-packages/MySQLdb/connections.py", line 259, in query
    _mysql.connection.query(self, query)
django.db.utils.ProgrammingError: (1146, "Table 'meiduo_mail_test.tb_oauth_qq' doesn't exist")
ERROR 2021-01-08 20:43:25,206 basehttp 154 "GET /oauth_callback/?code=3A5F99FAB94C9A8EE76936892AB6961B HTTP/1.1" 500 179300
INFO 2021-01-08 20:45:30,067 autoreload 217 /home/ubuntu/Desktop/test/day08/MeiDuo_test/meiduo_mail/meiduo_mail/settings.py changed, reloading.
INFO 2021-01-08 20:45:30,620 autoreload 597 Watching for file changes with StatReloader
ERROR 2021-01-08 20:45:33,555 log 228 Internal Server Error: /oauth_callback/
Traceback (most recent call last):
  File "/home/ubuntu/.virtualenvs/py3_shunyi_44/lib/python3.6/site-packages/django/core/handlers/exception.py", line 34, in inner
    response = get_response(request)
  File "/home/ubuntu/.virtualenvs/py3_shunyi_44/lib/python3.6/site-packages/django/core/handlers/base.py", line 115, in _get_response
    response = self.process_exception_by_middleware(e, request)
  File "/home/ubuntu/.virtualenvs/py3_shunyi_44/lib/python3.6/site-packages/django/core/handlers/base.py", line 113, in _get_response
    response = wrapped_callback(request, *callback_args, **callback_kwargs)
  File "/home/ubuntu/.virtualenvs/py3_shunyi_44/lib/python3.6/site-packages/django/views/generic/base.py", line 71, in view
    return self.dispatch(request, *args, **kwargs)
  File "/home/ubuntu/.virtualenvs/py3_shunyi_44/lib/python3.6/site-packages/django/views/generic/base.py", line 97, in dispatch
    return handler(request, *args, **kwargs)
  File "/home/ubuntu/Desktop/test/day08/MeiDuo_test/meiduo_mail/apps/oauth/views.py", line 24, in get
    access_token = qq.get_access_token(code)
  File "/home/ubuntu/.virtualenvs/py3_shunyi_44/lib/python3.6/site-packages/QQLoginTool/QQtool.py", line 63, in get_access_token
    raise Exception('access_token获取失败')
Exception: access_token获取失败
ERROR 2021-01-08 20:45:33,567 basehttp 154 "GET /oauth_callback/?code=3A5F99FAB94C9A8EE76936892AB6961B HTTP/1.1" 500 88830
INFO 2021-01-08 20:45:42,693 basehttp 154 "GET /oauth_callback/?code=F673F4D2C8AECC2B9792CBDDB68B00A1 HTTP/1.1" 200 27
WARNING 2021-01-08 20:45:43,670 log 228 Not Found: /carts/simple/
WARNING 2021-01-08 20:45:43,672 basehttp 154 "GET /carts/simple/ HTTP/1.1" 404 3477
INFO 2021-01-08 20:45:52,628 basehttp 154 "OPTIONS /logout/ HTTP/1.1" 200 0
INFO 2021-01-08 20:45:52,651 basehttp 154 "DELETE /logout/ HTTP/1.1" 200 27
INFO 2021-01-08 20:46:20,156 basehttp 154 "GET /oauth_callback/?code=9C5D573B8DE8971BF3D1B0637EBB162B HTTP/1.1" 200 65
INFO 2021-01-08 20:46:20,234 basehttp 154 "GET /image_codes/c148f951-3f05-4bbe-88f3-64b5ea1af3d8/ HTTP/1.1" 200 3639
INFO 2021-01-08 20:54:47,756 autoreload 217 /home/ubuntu/Desktop/test/day08/MeiDuo_test/meiduo_mail/apps/oauth/views.py changed, reloading.
INFO 2021-01-08 20:54:48,368 autoreload 597 Watching for file changes with StatReloader
INFO 2021-01-08 20:54:57,757 basehttp 154 "OPTIONS /login/ HTTP/1.1" 200 0
INFO 2021-01-08 20:54:57,785 basehttp 154 "POST /login/ HTTP/1.1" 200 51
INFO 2021-01-08 20:55:01,513 basehttp 154 "POST /login/ HTTP/1.1" 200 51
INFO 2021-01-08 20:55:02,302 basehttp 154 "POST /login/ HTTP/1.1" 200 51
INFO 2021-01-08 20:55:02,649 basehttp 154 "POST /login/ HTTP/1.1" 200 51
INFO 2021-01-08 20:55:02,816 basehttp 154 "POST /login/ HTTP/1.1" 200 51
INFO 2021-01-08 20:55:28,057 basehttp 154 "GET /oauth_callback/?code=189C553764BEF893E41F6126849F3065 HTTP/1.1" 200 27
WARNING 2021-01-08 20:55:28,899 log 228 Not Found: /carts/simple/
WARNING 2021-01-08 20:55:28,902 basehttp 154 "GET /carts/simple/ HTTP/1.1" 404 3477
INFO 2021-01-08 21:04:03,244 autoreload 217 /home/ubuntu/Desktop/test/day08/MeiDuo_test/meiduo_mail/apps/users/models.py changed, reloading.
INFO 2021-01-08 21:04:04,271 autoreload 597 Watching for file changes with StatReloader
INFO 2021-01-08 21:04:09,750 basehttp 154 "GET /info/ HTTP/1.1" 200 144
WARNING 2021-01-08 21:04:09,770 log 228 Not Found: /browse_histories/
WARNING 2021-01-08 21:04:09,771 basehttp 154 "GET /browse_histories/ HTTP/1.1" 404 3489
INFO 2021-01-08 21:05:23,979 autoreload 217 /home/ubuntu/Desktop/test/day08/MeiDuo_test/meiduo_mail/apps/users/urls.py changed, reloading.
INFO 2021-01-08 21:05:25,161 autoreload 597 Watching for file changes with StatReloader
INFO 2021-01-08 21:08:12,015 autoreload 217 /home/ubuntu/Desktop/test/day08/MeiDuo_test/meiduo_mail/meiduo_mail/settings.py changed, reloading.
INFO 2021-01-08 21:08:12,685 autoreload 597 Watching for file changes with StatReloader
INFO 2021-01-08 21:13:10,920 autoreload 217 /home/ubuntu/Desktop/test/day08/MeiDuo_test/meiduo_mail/celery_tasks/main.py changed, reloading.
INFO 2021-01-08 21:13:11,510 autoreload 597 Watching for file changes with StatReloader
INFO 2021-01-08 21:15:41,815 autoreload 217 /home/ubuntu/Desktop/test/day08/MeiDuo_test/meiduo_mail/manage.py changed, reloading.
INFO 2021-01-08 21:15:42,474 autoreload 597 Watching for file changes with StatReloader
INFO 2021-01-08 21:22:35,364 autoreload 217 /home/ubuntu/Desktop/test/day08/MeiDuo_test/meiduo_mail/celery_tasks/emails/tasks.py changed, reloading.
INFO 2021-01-08 21:22:36,086 autoreload 597 Watching for file changes with StatReloader
INFO 2021-01-08 21:23:27,093 autoreload 217 /home/ubuntu/Desktop/test/day08/MeiDuo_test/meiduo_mail/celery_tasks/emails/tasks.py changed, reloading.
INFO 2021-01-08 21:23:27,637 autoreload 597 Watching for file changes with StatReloader
INFO 2021-01-08 21:25:04,657 autoreload 217 /home/ubuntu/Desktop/test/day08/MeiDuo_test/meiduo_mail/celery_tasks/emails/tasks.py changed, reloading.
INFO 2021-01-08 21:25:05,177 autoreload 597 Watching for file changes with StatReloader
INFO 2021-01-08 21:26:55,540 autoreload 217 /home/ubuntu/Desktop/test/day08/MeiDuo_test/meiduo_mail/apps/users/views.py changed, reloading.
INFO 2021-01-08 21:26:59,101 autoreload 597 Watching for file changes with StatReloader
INFO 2021-01-08 21:29:58,983 autoreload 217 /home/ubuntu/Desktop/test/day08/MeiDuo_test/meiduo_mail/apps/users/views.py changed, reloading.
INFO 2021-01-08 21:29:59,706 autoreload 597 Watching for file changes with StatReloader
INFO 2021-01-08 21:35:29,465 autoreload 217 /home/ubuntu/Desktop/test/day08/MeiDuo_test/meiduo_mail/apps/users/views.py changed, reloading.
INFO 2021-01-08 21:35:30,446 autoreload 597 Watching for file changes with StatReloader
INFO 2021-01-08 21:37:09,854 autoreload 217 /home/ubuntu/Desktop/test/day08/MeiDuo_test/meiduo_mail/meiduo_mail/settings.py changed, reloading.
INFO 2021-01-08 21:37:10,735 autoreload 597 Watching for file changes with StatReloader
INFO 2021-01-08 21:37:18,828 autoreload 217 /home/ubuntu/Desktop/test/day08/MeiDuo_test/meiduo_mail/meiduo_mail/urls.py changed, reloading.
INFO 2021-01-08 21:37:19,443 autoreload 597 Watching for file changes with StatReloader
INFO 2021-01-08 21:37:56,035 autoreload 217 /home/ubuntu/Desktop/test/day08/MeiDuo_test/meiduo_mail/apps/areas/models.py changed, reloading.
INFO 2021-01-08 21:37:56,563 autoreload 597 Watching for file changes with StatReloader
INFO 2021-01-08 21:43:31,874 autoreload 217 /home/ubuntu/Desktop/test/day08/MeiDuo_test/meiduo_mail/apps/areas/views.py changed, reloading.
INFO 2021-01-08 21:43:32,342 autoreload 597 Watching for file changes with StatReloader
